Workbook

Sheet humaneval
A1: task_id | B1: dataset | C1: sample | D1: method | E1: passed | F1: failed | G1: error | H1: prompt | I1: raw_output | J1: code | K1: output_tokens | L1: gen_time_s | M1: mean_entropy | N1: max_entropy | O1: mean_margin | P1: min_margin | Q1: error_type | R1: error_message | S1: n_tokens | T1: entropy_mean | U1: entropy_std | V1: entropy_min | W1: entropy_max | X1: entropy_range | Y1: entropy_p90 | Z1: entropy_p95 | AA1: entropy_p99 | AB1: margin_mean | AC1: margin_std | AD1: margin_min | AE1: margin_p01 | AF1: margin_p05 | AG1: margin_p10 | AH1: n_entropy_gt_0_5 | AI1: n_entropy_gt_1_0 | AJ1: n_entropy_gt_1_5 | AK1: n_entropy_gt_2_0 | AL1: frac_entropy_gt_0_5 | AM1: frac_entropy_gt_1_0 | AN1: frac_entropy_gt_1_5 | AO1: n_margin_lt_0_05 | AP1: n_margin_lt_0_10 | AQ1: n_margin_lt_0_25 | AR1: n_margin_lt_0_50 | AS1: entropy_delta_abs_mean | AT1: entropy_delta_abs_max | AU1: entropy_delta_std | AV1: longest_entropy_gt_0_5_run | AW1: longest_entropy_gt_1_0_run | AX1: longest_entropy_gt_1_5_run | AY1: peak_valley_spikes | AZ1: burst_spike_run | BA1: code_lines | BB1: code_chars | BC1: raw_output_chars | BD1: group
A2: HumanEval/0 | B2: humaneval | C2: 0 | D2: baseline_deterministic | E2: TRUE | F2: FALSE | G2: {'type': None} | H2: from typing import List def has_close_elements(numbers: List[float], threshold: float) -> bool: """ Check if in given list of numbers, are any two numbers closer to each other than given threshold. >>> has_close_elements([1.0, 2.0, 3.0], 0.5) False >>> has_close_elements([1.0, 2.8, 3.0, 4.0, 5.0, 2.0], 0.3) True """ | I2: ```python from typing import List def has_close_elements(numbers: List[float], threshold: float) -> bool: for i in range(len(numbers)): for j in range(i + 1, len(numbers)): if abs(numbers[i] - numbers[j]) < threshold: return True return False ``` | J2: from typing import List def has_close_elements(numbers: List[float], threshold: float) -> bool: for i in range(len(numbers)): for j in range(i + 1, len(numbers)): if abs(numbers[i] - numbers[j]) < threshold: return True return False | K2: 68 | L2: 6.8494193 | M2: 0.038944983 | N2: 0.94724488 | O2: 10.931108 | P2: 1.15625 | S2: 68 | T2: 0.038944983 | U2: 0.1515154 | V2: 1.3757605e-06 | W2: 0.94724488 | X2: 0.94724351 | Y2: 0.03599484 | Z2: 0.19336686 | AA2: 0.7926706 | AB2: 10.931108 | AC2: 3.6743475 | AD2: 1.15625 | AE2: 1.8053125 | AF2: 3.124432 | AG2: 5.249859 | AH2: 2 | AI2: 0 | AJ2: 0 | AK2: 0 | AL2: 0.029411765 | AM2: 0 | AN2: 0 | AO2: 0 | AP2: 0 | AQ2: 0 | AR2: 0 | AS2: 0.059960622 | AT2: 0.9469509 | AU2: 0.19751702 | AV2: 1 | AW2: 0 | AX2: 0 | AY2: 0 | AZ2: 0 | BA2: 8 | BB2: 277 | BC2: 291 | BD2: Pass
A3: HumanEval/1 | B3: humaneval | C3: 0 | D3: baseline_deterministic | E3: TRUE | F3: FALSE | G3: {'type': None} | H3: from typing import List def separate_paren_groups(paren_string: str) -> List[str]: """ Input to this function is a string containing multiple groups of nested parentheses. Your goal is to separate those group into separate strings and return the list of those. Separate groups are balanced (each open brace is properly closed) and not nested within each other Ignore any spaces in the input string. >>> separate_paren_groups('( ) (( )) (( )( ))') ['()', '(())', '(()())'] """ | I3: ```python from typing import List def separate_paren_groups(paren_string: str) -> List[str]: result = [] current_group = [] depth = 0 for char in paren_string.replace(' ', ''): if char == '(': depth += 1 current_group.append(char) elif char == ')': depth -= 1 current_group.append(char) if depth == 0: result.append(''.join(current_group)) current_group = [] return result ``` | J3: from typing import List def separate_paren_groups(paren_string: str) -> List[str]: result = [] current_group = [] depth = 0 for char in paren_string.replace(' ', ''): if char == '(': depth += 1 current_group.append(char) elif char == ')': depth -= 1 current_group.append(char) if depth == 0: result.append(''.join(current_group)) current_group = [] return result | K3: 111 | L3: 7.4449092 | M3: 0.064491988 | N3: 0.90689397 | O3: 10.27761 | P3: 0.12784004 | S3: 111 | T3: 0.064491988 | U3: 0.19070704 | V3: 1.2766128e-07 | W3: 0.90689397 | X3: 0.90689384 | Y3: 0.089895874 | Z3: 0.55039287 | AA3: 0.89673977 | AB3: 10.27761 | AC3: 4.2862837 | AD3: 0.12784004 | AE3: 0.28991489 | AF3: 1.84375 | AG3: 4.144886 | AH3: 6 | AI3: 0 | AJ3: 0 | AK3: 0 | AL3: 0.054054054 | AM3: 0 | AN3: 0 | AO3: 0 | AP3: 0 | AQ3: 1 | AR3: 2 | AS3: 0.11386651 | AT3: 0.90467545 | AU3: 0.2652809 | AV3: 1 | AW3: 0 | AX3: 0 | AY3: 0 | AZ3: 0 | BA3: 19 | BB3: 493 | BC3: 507 | BD3: Pass
A4: HumanEval/2 | B4: humaneval | C4: 0 | D4: baseline_deterministic | E4: TRUE | F4: FALSE | G4: {'type': None} | H4: def truncate_number(number: float) -> float: """ Given a positive floating point number, it can be decomposed into and integer part (largest integer smaller than given number) and decimals (leftover part always smaller than 1). Return the decimal part of the number. >>> truncate_number(3.5) 0.5 """ | I4: ```python def truncate_number(number: float) -> float: return number - int(number) ``` | J4: def truncate_number(number: float) -> float: return number - int(number) | K4: 22 | L4: 1.4743642 | M4: 0.06573696 | N4: 0.72922671 | O4: 8.3476245 | P4: 1.477272 | S4: 22 | T4: 0.06573696 | U4: 0.17648287 | V4: 3.066604e-05 | W4: 0.72922671 | X4: 0.72919604 | Y4: 0.12100854 | Z4: 0.4282833 | AA4: 0.66931793 | AB4: 8.3476245 | AC4: 3.3785621 | AD4: 1.477272 | AE4: 1.6923433 | AF4: 2.5625005 | AG4: 3.8710224 | AH4: 1 | AI4: 0 | AJ4: 0 | AK4: 0 | AL4: 0.045454545 | AM4: 0 | AN4: 0 | AO4: 0 | AP4: 0 | AQ4: 0 | AR4: 0 | AS4: 0.094460238 | AT4: 0.72703638 | AU4: 0.20951935 | AV4: 1 | AW4: 0 | AX4: 0 | AY4: 0 | AZ4: 0 | BA4: 2 | BB4: 76 | BC4: 90 | BD4: Pass
A5: HumanEval/3 | B5: humaneval | C5: 0 | D5: baseline_deterministic | E5: TRUE | F5: FALSE | G5: {'type': None} | H5: from typing import List def below_zero(operations: List[int]) -> bool: """ You're given a list of deposit and withdrawal operations on a bank account that starts with zero balance. Your task is to detect if at any point the balance of account fallls below zero, and at that point function should return True. Otherwise it should return False. >>> below_zero([1, 2, 3]) False >>> below_zero([1, 2, -4, 5]) True """ | I5: ```python from typing import List def below_zero(operations: List[int]) -> bool: balance = 0 for operation in operations: balance += operation if balance < 0: return True return False ``` | J5: from typing import List def below_zero(operations: List[int]) -> bool: balance = 0 for operation in operations: balance += operation if balance < 0: return True return False | K5: 54 | L5: 3.6386415 | M5: 0.037913217 | N5: 0.54440379 | O5: 10.495147 | P5: 1.786932 | S5: 54 | T5: 0.037913217 | U5: 0.1162561 | V5: 5.8322394e-07 | W5: 0.54440379 | X5: 0.54440321 | Y5: 0.06065647 | Z5: 0.37388357 | AA5: 0.47988176 | AB5: 10.495147 | AC5: 3.6842977 | AD5: 1.786932 | AE5: 1.7884372 | AF5: 2.0757812 | AG5: 4.8455976 | AH5: 1 | AI5: 0 | AJ5: 0 | AK5: 0 | AL5: 0.018518519 | AM5: 0 | AN5: 0 | AO5: 0 | AP5: 0 | AQ5: 0 | AR5: 0 | AS5: 0.061193795 | AT5: 0.54189218 | AU5: 0.14925609 | AV5: 1 | AW5: 0 | AX5: 0 | AY5: 0 | AZ5: 0 | BA5: 9 | BB5: 214 | BC5: 228 | BD5: Pass
A6: HumanEval/4 | B6: humaneval | C6: 0 | D6: baseline_deterministic | E6: TRUE | F6: FALSE | G6: {'type': None} | H6: from typing import List def mean_absolute_deviation(numbers: List[float]) -> float: """ For a given list of input numbers, calculate Mean Absolute Deviation around the mean of this dataset. Mean Absolute Deviation is the average absolute difference between each element and a centerpoint (mean in this case): MAD = average | x - x_mean | >>> mean_absolute_deviation([1.0, 2.0, 3.0, 4.0]) 1.0 """ | I6: ```python from typing import List def mean_absolute_deviation(numbers: List[float]) -> float: mean = sum(numbers) / len(numbers) return sum(abs(x - mean) for x in numbers) / len(numbers) ``` | J6: from typing import List def mean_absolute_deviation(numbers: List[float]) -> float: mean = sum(numbers) / len(numbers) return sum(abs(x - mean) for x in numbers) / len(numbers) | K6: 50 | L6: 3.4043807 | M6: 0.080597076 | N6: 1.0592155 | O6: 9.3280261 | P6: 0.18465805 | S6: 50 | T6: 0.080597076 | U6: 0.23705056 | V6: 8.9779123e-06 | W6: 1.0592155 | X6: 1.0592066 | Y6: 0.097900273 | Z6: 0.67773569 | AA6: 1.0252042 | AB6: 9.3280261 | AC6: 3.9965491 | AD6: 0.18465805 | AE6: 0.53058186 | AF6: 1.1259944 | AG6: 4.4920448 | AH6: 4 | AI6: 1 | AJ6: 0 | AK6: 0 | AL6: 0.08 | AM6: 0.02 | AN6: 0 | AO6: 0 | AP6: 0 | AQ6: 1 | AR6: 1 | AS6: 0.13319676 | AT6: 1.0584926 | AU6: 0.32451756 | AV6: 1 | AW6: 1 | AX6: 0 | AY6: 0 | AZ6: 1 | BA6: 5 | BB6: 185 | BC6: 199 | BD6: Pass
A7: HumanEval/5 | B7: humaneval | C7: 0 | D7: baseline_deterministic | E7: TRUE | F7: FALSE | G7: {'type': None} | H7: from typing import List def intersperse(numbers: List[int], delimeter: int) -> List[int]: """ Insert a number 'delimeter' between every two consecutive elements of input list `numbers' >>> intersperse([], 4) [] >>> intersperse([1, 2, 3], 4) [1, 4, 2, 4, 3] """ | I7: ```python from typing import List def intersperse(numbers: List[int], delimiter: int) -> List[int]: result = [] for i, num in enumerate(numbers): result.append(num) if i < len(numbers) - 1: result.append(delimiter) return result ``` | J7: from typing import List def intersperse(numbers: List[int], delimiter: int) -> List[int]: result = [] for i, num in enumerate(numbers): result.append(num) if i < len(numbers) - 1: result.append(delimiter) return result | K7: 65 | L7: 4.3282141 | M7: 0.076676901 | N7: 0.90023786 | O7: 9.6018906 | P7: 0.015625 | S7: 65 | T7: 0.076676901 | U7: 0.19895919 | V7: 1.4214147e-06 | W7: 0.90023786 | X7: 0.90023644 | Y7: 0.21074783 | Z7: 0.57395328 | AA7: 0.83114167 | AB7: 9.6018906 | AC7: 4.3085445 | AD7: 0.015625 | AE7: 0.28289795 | AF7: 1.2551147 | AG7: 3.1409088 | AH7: 6 | AI7: 0 | AJ7: 0 | AK7: 0 | AL7: 0.092307692 | AM7: 0 | AN7: 0 | AO7: 1 | AP7: 1 | AQ7: 1 | AR7: 2 | AS7: 0.11330989 | AT7: 0.89974878 | AU7: 0.25432959 | AV7: 2 | AW7: 0 | AX7: 0 | AY7: 0 | AZ7: 0 | BA7: 9 | BB7: 259 | BC7: 273 | BD7: Pass
A8: HumanEval/6 | B8: humaneval | C8: 0 | D8: baseline_deterministic | E8: TRUE | F8: FALSE | G8: {'type': None} | H8: from typing import List def parse_nested_parens(paren_string: str) -> List[int]: """ Input to this function is a string represented multiple groups for nested parentheses separated by spaces. For each of the group, output the deepest level of nesting of parentheses. E.g. (()()) has maximum two levels of nesting while ((())) has three. >>> parse_nested_parens('(()()) ((())) () ((())()())') [2, 3, 1, 3] """ | I8: ```python from typing import List def parse_nested_parens(paren_string: str) -> List[int]: result = [] for group in paren_string.split(): depth = max_depth = 0 for char in group: if char == '(': depth += 1 max_depth = max(max_depth, depth) elif char == ')': depth -= 1 result.append(max_depth) return result ``` | J8: from typing import List def parse_nested_parens(paren_string: str) -> List[int]: result = [] for group in paren_string.split(): depth = max_depth = 0 for char in group: if char == '(': depth += 1 max_depth = max(max_depth, depth) elif char == ')': depth -= 1 result.append(max_depth) return result | K8: 96 | L8: 6.4661657 | M8: 0.067659937 | N8: 1.6361785 | O8: 10.351112 | P8: 0.015625 | S8: 96 | T8: 0.067659937 | U8: 0.22197129 | V8: 7.7469855e-07 | W8: 1.6361785 | X8: 1.6361777 | Y8: 0.19514153 | Z8: 0.50082266 | AA8: 0.90449341 | AB8: 10.351112 | AC8: 4.2466624 | AD8: 0.015625 | AE8: 0.2828125 | AF8: 1.4151278 | AG8: 3.038352 | AH8: 5 | AI8: 1 | AJ8: 1 | AK8: 0 | AL8: 0.052083333 | AM8: 0.010416667 | AN8: 0.010416667 | AO8: 1 | AP8: 1 | AQ8: 1 | AR8: 2 | AS8: 0.10468314 | AT8: 1.6360386 | AU8: 0.29796033 | AV8: 1 | AW8: 1 | AX8: 1 | AY8: 0 | AZ8: 1 | BA8: 14 | BB8: 406 | BC8: 420 | BD8: Pass
A9: HumanEval/7 | B9: humaneval | C9: 0 | D9: baseline_deterministic | E9: TRUE | F9: FALSE | G9: {'type': None} | H9: from typing import List def filter_by_substring(strings: List[str], substring: str) -> List[str]: """ Filter an input list of strings only for ones that contain given substring >>> filter_by_substring([], 'a') [] >>> filter_by_substring(['abc', 'bacd', 'cde', 'array'], 'a') ['abc', 'bacd', 'array'] """ | I9: ```python from typing import List def filter_by_substring(strings: List[str], substring: str) -> List[str]: return [s for s in strings if substring in s] ``` | J9: from typing import List def filter_by_substring(strings: List[str], substring: str) -> List[str]: return [s for s in strings if substring in s] | K9: 41 | L9: 2.7362653 | M9: 0.06401249 | N9: 0.74872035 | O9: 9.6356886 | P9: 1.352272 | S9: 41 | T9: 0.06401249 | U9: 0.17150069 | V9: 7.7235873e-06 | W9: 0.74872035 | X9: 0.74871262 | Y9: 0.26676482 | Z9: 0.51785553 | AA9: 0.65690168 | AB9: 9.6356886 | AC9: 3.7416307 | AD9: 1.352272 | AE9: 1.4727264 | AF9: 2.1448879 | AG9: 2.546875 | AH9: 3 | AI9: 0 | AJ9: 0 | AK9: 0 | AL9: 0.073170732 | AM9: 0 | AN9: 0 | AO9: 0 | AP9: 0 | AQ9: 0 | AR9: 0 | AS9: 0.091302301 | AT9: 0.74645616 | AU9: 0.21583202 | AV9: 1 | AW9: 0 | AX9: 0 | AY9: 0 | AZ9: 0 | BA9: 4 | BB9: 148 | BC9: 162 | BD9: Pass
A10: HumanEval/8 | B10: humaneval | C10: 0 | D10: baseline_deterministic | E10: TRUE | F10: FALSE | G10: {'type': None} | H10: from typing import List, Tuple def sum_product(numbers: List[int]) -> Tuple[int, int]: """ For a given list of integers, return a tuple consisting of a sum and a product of all the integers in a list. Empty sum should be equal to 0 and empty product should be equal to 1. >>> sum_product([]) (0, 1) >>> sum_product([1, 2, 3, 4]) (10, 24) """ | I10: ```python from typing import List, Tuple def sum_product(numbers: List[int]) -> Tuple[int, int]: if not numbers: return (0, 1) total_sum = sum(numbers) total_product = 1 for number in numbers: total_product *= number return (total_sum, total_product) ``` | J10: from typing import List, Tuple def sum_product(numbers: List[int]) -> Tuple[int, int]: if not numbers: return (0, 1) total_sum = sum(numbers) total_product = 1 for number in numbers: total_product *= number return (total_sum, total_product) | K10: 75 | L10: 5.0417852 | M10: 0.076868743 | N10: 1.1571183 | O10: 9.5909096 | P10: 0.796875 | S10: 75 | T10: 0.076868743 | U10: 0.20516828 | V10: 3.2629498e-06 | W10: 1.1571183 | X10: 1.1571151 | Y10: 0.21294627 | Z10: 0.50669127 | AA10: 0.99532377 | AB10: 9.5909096 | AC10: 4.1987145 | AD10: 0.796875 | AE10: 0.81789696 | AF10: 1.5923288 | AG10: 3.095171 | AH10: 4 | AI10: 1 | AJ10: 0 | AK10: 0 | AL10: 0.053333333 | AM10: 0.013333333 | AN10: 0 | AO10: 0 | AP10: 0 | AQ10: 0 | AR10: 0 | AS10: 0.1317978 | AT10: 1.1527553 | AU10: 0.27957244 | AV10: 1 | AW10: 1 | AX10: 0 | AY10: 0 | AZ10: 1 | BA10: 12 | BB10: 287 | BC10: 301 | BD10: Pass
A11: HumanEval/9 | B11: humaneval | C11: 0 | D11: baseline_deterministic | E11: TRUE | F11: FALSE | G11: {'type': None} | H11: from typing import List, Tuple def rolling_max(numbers: List[int]) -> List[int]: """ From a given list of integers, generate a list of rolling maximum element found until given moment in the sequence. >>> rolling_max([1, 2, 3, 2, 3, 4, 2]) [1, 2, 3, 3, 3, 4, 4] """ | I11: ```python from typing import List, Tuple def rolling_max(numbers: List[int]) -> List[int]: if not numbers: return [] result = [] current_max = float('-inf') for number in numbers: current_max = max(current_max, number) result.append(current_max) return result ``` | J11: from typing import List, Tuple def rolling_max(numbers: List[int]) -> List[int]: if not numbers: return [] result = [] current_max = float('-inf') for number in numbers: current_max = max(current_max, number) result.append(current_max) return result | K11: 72 | L11: 4.8260712 | M11: 0.12914795 | N11: 1.3569288 | O11: 9.2316332 | P11: 0.22301102 | S11: 72 | T11: 0.12914795 | U11: 0.2851342 | V11: 5.7710049e-06 | W11: 1.3569288 | X11: 1.3569231 | Y11: 0.62040457 | Z11: 0.74548785 | AA11: 1.0993967 | AB11: 9.2316332 | AC11: 4.825562 | AD11: 0.22301102 | AE11: 0.25326694 | AF11: 0.58884935 | AG11: 0.96732903 | AH11: 10 | AI11: 1 | AJ11: 0 | AK11: 0 | AL11: 0.13888889 | AM11: 0.013888889 | AN11: 0 | AO11: 0 | AP11: 0 | AQ11: 1 | AR11: 3 | AS11: 0.23262122 | AT11: 1.3553417 | AU11: 0.41765592 | AV11: 1 | AW11: 1 | AX11: 0 | AY11: 0 | AZ11: 1 | BA11: 13 | BB11: 304 | BC11: 318 | BD11: Pass
A12: HumanEval/10 | B12: humaneval | C12: 0 | D12: baseline_deterministic | E12: FALSE | F12: TRUE | G12: {'type': 'RuntimeError', 'message': "NameError: name 'is_palindrome' is not defined. Did you mean: 'make_palindrome'?", 'stderr_tail': 'Traceback (most recent call last):\n File "/tmp/tmpt4uudtga/candidate_eval.py", line 47, in <module>\n check(make_palindrome)\n File "/tmp/tmpt4uudtga/candidate_eval.py", line 40, in check\n assert candidate(\'\') == \'\'\n ^^^^^^^^^^^^^\n File "/tmp/tmpt4uudtga/candidate_eval.py", line 27, in make_palindrome\n if is_palindrome(string[:i]):\n ^^^^^^^^^^^^^\nNameError: name \'is_palindrome\' is not defined. Did you mean: \'make_palindrome\'?\n', 'stdout_tail': ''} | H12: def is_palindrome(string: str) -> bool: """ Test if given string is a palindrome """ return string == string[::-1] def make_palindrome(string: str) -> str: """ Find the shortest palindrome that begins with a supplied string. Algorithm idea is simple: - Find the longest postfix of supplied string that is a palindrome. - Append to the end of the string reverse of a string prefix that comes before the palindromic suffix. >>> make_palindrome('') '' >>> make_palindrome('cat') 'catac' >>> make_palindrome('cata') 'catac' """ | I12: ```python def make_palindrome(string: str) -> str: """ Find the shortest palindrome that begins with a supplied string. Algorithm idea is simple: - Find the longest postfix of supplied string that is a palindrome. - Append to the end of the string reverse of a string prefix that comes before the palindromic suffix. >>> make_palindrome('') '' >>> make_palindrome('cat') 'catac' >>> make_palindrome('cata') 'catac' """ n = len(string) for i in range(n, -1, -1): if is_palindrome(string[:i]): return string + string[i-1::-1] return string ``` | J12: def make_palindrome(string: str) -> str: """ Find the shortest palindrome that begins with a supplied string. Algorithm idea is simple: - Find the longest postfix of supplied string that is a palindrome. - Append to the end of the string reverse of a string prefix that comes before the palindromic suffix. >>> make_palindrome('') '' >>> make_palindrome('cat') 'catac' >>> make_palindrome('cata') 'catac' """ n = len(string) for i in range(n, -1, -1): if is_palindrome(string[:i]): return string + string[i-1::-1] return string | K12: 155 | L12: 10.442714 | M12: 0.062950663 | N12: 1.3502294 | O12: 9.3640952 | P12: 0.78267097 | Q12: RuntimeError | R12: NameError: name 'is_palindrome' is not defined. Did you mean: 'make_palindrome'? | S12: 155 | T12: 0.062950663 | U12: 0.19747266 | V12: 1.3598124e-05 | W12: 1.3502294 | X12: 1.3502158 | Y12: 0.11780825 | Z12: 0.51041974 | AA12: 0.94273655 | AB12: 9.3640952 | AC12: 3.4438279 | AD12: 0.78267097 | AE12: 1.1125286 | AF12: 1.7525558 | AG12: 4.067046 | AH12: 9 | AI12: 2 | AJ12: 0 | AK12: 0 | AL12: 0.058064516 | AM12: 0.012903226 | AN12: 0 | AO12: 0 | AP12: 0 | AQ12: 0 | AR12: 0 | AS12: 0.10592388 | AT12: 1.3442262 | AU12: 0.27177335 | AV12: 1 | AW12: 1 | AX12: 0 | AY12: 0 | AZ12: 1 | BA12: 17 | BB12: 603 | BC12: 617 | BD12: Other_fail
A13: HumanEval/11 | B13: humaneval | C13: 0 | D13: baseline_deterministic | E13: TRUE | F13: FALSE | G13: {'type': None} | H13: from typing import List def string_xor(a: str, b: str) -> str: """ Input are two strings a and b consisting only of 1s and 0s. Perform binary XOR on these inputs and return result also as a string. >>> string_xor('010', '110') '100' """ | I13: ```python from typing import List def string_xor(a: str, b: str) -> str: """ Input are two strings a and b consisting only of 1s and 0s. Perform binary XOR on these inputs and return result also as a string. >>> string_xor('010', '110') '100' """ return ''.join(str(int(x) ^ int(y)) for x, y in zip(a, b)) ``` | J13: from typing import List def string_xor(a: str, b: str) -> str: """ Input are two strings a and b consisting only of 1s and 0s. Perform binary XOR on these inputs and return result also as a string. >>> string_xor('010', '110') '100' """ return ''.join(str(int(x) ^ int(y)) for x, y in zip(a, b)) | K13: 103 | L13: 6.8013432 | M13: 0.059633229 | N13: 1.1092231 | O13: 10.071313 | P13: 0.25568199 | S13: 103 | T13: 0.059633229 | U13: 0.19294062 | V13: 3.882607e-06 | W13: 1.1092231 | X13: 1.1092192 | Y13: 0.11876967 | Z13: 0.56860641 | AA13: 0.84508218 | AB13: 10.071313 | AC13: 3.6895284 | AD13: 0.25568199 | AE13: 0.75042599 | AF13: 1.7309652 | AG13: 4.7036934 | AH13: 6 | AI13: 1 | AJ13: 0 | AK13: 0 | AL13: 0.058252427 | AM13: 0.0097087379 | AN13: 0 | AO13: 0 | AP13: 0 | AQ13: 0 | AR13: 1 | AS13: 0.091989847 | AT13: 1.1063916 | AU13: 0.24802652 | AV13: 1 | AW13: 1 | AX13: 0 | AY13: 0 | AZ13: 1 | BA13: 9 | BB13: 320 | BC13: 334 | BD13: Pass
A14: HumanEval/12 | B14: humaneval | C14: 0 | D14: baseline_deterministic | E14: TRUE | F14: FALSE | G14: {'type': None} | H14: from typing import List, Optional def longest(strings: List[str]) -> Optional[str]: """ Out of list of strings, return the longest one. Return the first one in case of multiple strings of the same length. Return None in case the input list is empty. >>> longest([]) >>> longest(['a', 'b', 'c']) 'a' >>> longest(['a', 'bb', 'ccc']) 'ccc' """ | I14: ```python from typing import List, Optional def longest(strings: List[str]) -> Optional[str]: if not strings: return None return max(strings, key=len) ``` | J14: from typing import List, Optional def longest(strings: List[str]) -> Optional[str]: if not strings: return None return max(strings, key=len) | K14: 40 | L14: 2.7086916 | M14: 0.056988135 | N14: 0.50766248 | O14: 8.670384 | P14: 1.822443 | S14: 40 | T14: 0.056988135 | U14: 0.12458233 | V14: 8.8003098e-06 | W14: 0.50766248 | X14: 0.50765367 | Y14: 0.18898669 | Z14: 0.39503533 | AA14: 0.46954635 | AB14: 8.670384 | AC14: 3.6428547 | AD14: 1.822443 | AE14: 1.8706388 | AF14: 2.7057513 | AG14: 3.1910513 | AH14: 1 | AI14: 0 | AJ14: 0 | AK14: 0 | AL14: 0.025 | AM14: 0 | AN14: 0 | AO14: 0 | AP14: 0 | AQ14: 0 | AR14: 0 | AS14: 0.09884305 | AT14: 0.50727004 | AU14: 0.18042414 | AV14: 1 | AW14: 0 | AX14: 0 | AY14: 0 | AZ14: 0 | BA14: 6 | BB14: 157 | BC14: 171 | BD14: Pass
A15: HumanEval/13 | B15: humaneval | C15: 0 | D15: baseline_deterministic | E15: TRUE | F15: FALSE | G15: {'type': None} | H15: def greatest_common_divisor(a: int, b: int) -> int: """ Return a greatest common divisor of two integers a and b >>> greatest_common_divisor(3, 5) 1 >>> greatest_common_divisor(25, 15) 5 """ | I15: ```python def greatest_common_divisor(a: int, b: int) -> int: while b != 0: a, b = b, a % b return a ``` | J15: def greatest_common_divisor(a: int, b: int) -> int: while b != 0: a, b = b, a % b return a | K15: 43 | L15: 2.8360017 | M15: 0.077366587 | N15: 1.0636663 | O15: 9.4085629 | P15: 0.59517097 | S15: 43 | T15: 0.077366587 | U15: 0.23591415 | V15: 1.5137123e-06 | W15: 1.0636663 | X15: 1.0636648 | Y15: 0.1273774 | Z15: 0.59771966 | AA15: 1.031328 | AB15: 9.4085629 | AC15: 4.0022243 | AD15: 0.59517097 | AE15: 0.66019917 | AF15: 1.7684652 | AG15: 3.5707386 | AH15: 3 | AI15: 1 | AJ15: 0 | AK15: 0 | AL15: 0.069767442 | AM15: 0.023255814 | AN15: 0 | AO15: 0 | AP15: 0 | AQ15: 0 | AR15: 0 | AS15: 0.12237155 | AT15: 1.0461464 | AU15: 0.30805729 | AV15: 1 | AW15: 1 | AX15: 0 | AY15: 0 | AZ15: 1 | BA15: 4 | BB15: 106 | BC15: 120 | BD15: Pass
A16: HumanEval/14 | B16: humaneval | C16: 0 | D16: baseline_deterministic | E16: TRUE | F16: FALSE | G16: {'type': None} | H16: from typing import List def all_prefixes(string: str) -> List[str]: """ Return list of all prefixes from shortest to longest of the input string >>> all_prefixes('abc') ['a', 'ab', 'abc'] """ | I16: ```python from typing import List def all_prefixes(string: str) -> List[str]: return [string[:i] for i in range(1, len(string) + 1)] ``` | J16: from typing import List def all_prefixes(string: str) -> List[str]: return [string[:i] for i in range(1, len(string) + 1)] | K16: 43 | L16: 2.8365608 | M16: 0.071679214 | N16: 0.88573432 | O16: 10.192588 | P16: 0.10653305 | S16: 43 | T16: 0.071679214 | U16: 0.20168868 | V16: 8.0795627e-07 | W16: 0.88573432 | X16: 0.88573351 | Y16: 0.14961665 | Z16: 0.66093926 | AA16: 0.81168131 | AB16: 10.192588 | AC16: 4.6815219 | AD16: 0.10653305 | AE16: 0.15664742 | AF16: 1.0188921 | AG16: 3.5607956 | AH16: 3 | AI16: 0 | AJ16: 0 | AK16: 0 | AL16: 0.069767442 | AM16: 0 | AN16: 0 | AO16: 0 | AP16: 0 | AQ16: 2 | AR16: 2 | AS16: 0.10585645 | AT16: 0.88319897 | AU16: 0.24695493 | AV16: 1 | AW16: 0 | AX16: 0 | AY16: 0 | AZ16: 0 | BA16: 4 | BB16: 127 | BC16: 142 | BD16: Pass
A17: HumanEval/15 | B17: humaneval | C17: 0 | D17: baseline_deterministic | E17: TRUE | F17: FALSE | G17: {'type': None} | H17: def string_sequence(n: int) -> str: """ Return a string containing space-delimited numbers starting from 0 upto n inclusive. >>> string_sequence(0) '0' >>> string_sequence(5) '0 1 2 3 4 5' """ | I17: ```python def string_sequence(n: int) -> str: return ' '.join(str(i) for i in range(n + 1)) ``` | J17: def string_sequence(n: int) -> str: return ' '.join(str(i) for i in range(n + 1)) | K17: 32 | L17: 2.1127557 | M17: 0.067144941 | N17: 0.65725547 | O17: 10.01254 | P17: 1.568182 | S17: 32 | T17: 0.067144941 | U17: 0.15885294 | V17: 1.1587908e-06 | W17: 0.65725547 | X17: 0.65725431 | Y17: 0.24801183 | Z17: 0.4372939 | AA17: 0.59653513 | AB17: 10.01254 | AC17: 4.7477362 | AD17: 1.568182 | AE17: 1.6470029 | AF17: 1.8950996 | AG17: 2.66875 | AH17: 1 | AI17: 0 | AJ17: 0 | AK17: 0 | AL17: 0.03125 | AM17: 0 | AN17: 0 | AO17: 0 | AP17: 0 | AQ17: 0 | AR17: 0 | AS17: 0.10994862 | AT17: 0.65418749 | AU17: 0.2063012 | AV17: 1 | AW17: 0 | AX17: 0 | AY17: 0 | AZ17: 0 | BA17: 2 | BB17: 85 | BC17: 99 | BD17: Pass
A18: HumanEval/16 | B18: humaneval | C18: 0 | D18: baseline_deterministic | E18: TRUE | F18: FALSE | G18: {'type': None} | H18: def count_distinct_characters(string: str) -> int: """ Given a string, find out how many distinct characters (regardless of case) does it consist of >>> count_distinct_characters('xyzXYZ') 3 >>> count_distinct_characters('Jerry') 4 """ | I18: ```python def count_distinct_characters(string: str) -> int: return len(set(string.lower())) ``` | J18: def count_distinct_characters(string: str) -> int: return len(set(string.lower())) | K18: 24 | L18: 1.5932222 | M18: 0.090218814 | N18: 0.61896223 | O18: 7.950255 | P18: 1.606535 | S18: 24 | T18: 0.090218814 | U18: 0.18610724 | V18: 2.9160576e-05 | W18: 0.61896223 | X18: 0.61893307 | Y18: 0.43598098 | Z18: 0.48677768 | AA18: 0.58983185 | AB18: 7.950255 | AC18: 3.6254645 | AD18: 1.606535 | AE18: 1.698012 | AF18: 2.1174005 | AG18: 2.9869331 | AH18: 1 | AI18: 0 | AJ18: 0 | AK18: 0 | AL18: 0.041666667 | AM18: 0 | AN18: 0 | AO18: 0 | AP18: 0 | AQ18: 0 | AR18: 0 | AS18: 0.14958998 | AT18: 0.61601831 | AU18: 0.25596756 | AV18: 1 | AW18: 0 | AX18: 0 | AY18: 0 | AZ18: 0 | BA18: 2 | BB18: 86 | BC18: 100 | BD18: Pass
A19: HumanEval/17 | B19: humaneval | C19: 0 | D19: baseline_deterministic | E19: TRUE | F19: FALSE | G19: {'type': None} | H19: from typing import List def parse_music(music_string: str) -> List[int]: """ Input to this function is a string representing musical notes in a special ASCII format. Your task is to parse this string and return list of integers corresponding to how many beats does each not last. Here is a legend: 'o' - whole note, lasts four beats 'o|' - half note, lasts two beats '.|' - quater note, lasts one beat >>> parse_music('o o| .| o| o| .| .| .| .| o o') [4, 2, 1, 2, 2, 1, 1, 1, 1, 4, 4] """ | I19: ```python from typing import List def parse_music(music_string: str) -> List[int]: """ Input to this function is a string representing musical notes in a special ASCII format. Your task is to parse this string and return list of integers corresponding to how many beats does each note last. Here is a legend: 'o' - whole note, lasts four beats 'o|' - half note, lasts two beats '.|' - quarter note, lasts one beat >>> parse_music('o o| .| o| o| .| .| .| .| o o') [4, 2, 1, 2, 2, 1, 1, 1, 1, 4, 4] """ note_map = {'o': 4, 'o|': 2, '.|': 1} return [note_map[note] for note in music_string.split()] ``` | J19: from typing import List def parse_music(music_string: str) -> List[int]: """ Input to this function is a string representing musical notes in a special ASCII format. Your task is to parse this string and return list of integers corresponding to how many beats does each note last. Here is a legend: 'o' - whole note, lasts four beats 'o|' - half note, lasts two beats '.|' - quarter note, lasts one beat >>> parse_music('o o| .| o| o| .| .| .| .| o o') [4, 2, 1, 2, 2, 1, 1, 1, 1, 4, 4] """ note_map = {'o': 4, 'o|': 2, '.|': 1} return [note_map[note] for note in music_string.split()] | K19: 208 | L19: 14.136534 | M19: 0.049633345 | N19: 1.9797019 | O19: 10.700384 | P19: 0.12784195 | S19: 208 | T19: 0.049633345 | U19: 0.21596802 | V19: 1.0875229e-05 | W19: 1.9797019 | X19: 1.979691 | Y19: 0.031460848 | Z19: 0.34241218 | AA19: 0.72332259 | AB19: 10.700384 | AC19: 3.400452 | AD19: 0.12784195 | AE19: 0.55582472 | AF19: 2.6765627 | AG19: 5.8480108 | AH19: 6 | AI19: 2 | AJ19: 2 | AK19: 0 | AL19: 0.028846154 | AM19: 0.0096153846 | AN19: 0.0096153846 | AO19: 0 | AP19: 0 | AQ19: 1 | AR19: 3 | AS19: 0.078958554 | AT19: 1.8821417 | AU19: 0.26786943 | AV19: 2 | AW19: 1 | AX19: 1 | AY19: 0 | AZ19: 1 | BA19: 17 | BB19: 636 | BC19: 650 | BD19: Pass
A20: HumanEval/18 | B20: humaneval | C20: 0 | D20: baseline_deterministic | E20: TRUE | F20: FALSE | G20: {'type': None} | H20: def how_many_times(string: str, substring: str) -> int: """ Find how many times a given substring can be found in the original string. Count overlaping cases. >>> how_many_times('', 'a') 0 >>> how_many_times('aaa', 'a') 3 >>> how_many_times('aaaa', 'aa') 3 """ | I20: ```python def how_many_times(string: str, substring: str) -> int: count = 0 start = 0 while True: start = string.find(substring, start) if start == -1: break count += 1 start += 1 return count ``` | J20: def how_many_times(string: str, substring: str) -> int: count = 0 start = 0 while True: start = string.find(substring, start) if start == -1: break count += 1 start += 1 return count | K20: 72 | L20: 4.7681453 | M20: 0.06850435 | N20: 0.71194214 | O20: 9.6497499 | P20: 0.32670593 | S20: 72 | T20: 0.06850435 | U20: 0.16972679 | V20: 2.9775072e-07 | W20: 0.71194214 | X20: 0.71194184 | Y20: 0.31978745 | Z20: 0.45148027 | AA20: 0.69570812 | AB20: 9.6497499 | AC20: 4.3081455 | AD20: 0.32670593 | AE20: 0.79365097 | AF20: 2.0987207 | AG20: 2.5367897 | AH20: 3 | AI20: 0 | AJ20: 0 | AK20: 0 | AL20: 0.041666667 | AM20: 0 | AN20: 0 | AO20: 0 | AP20: 0 | AQ20: 0 | AR20: 1 | AS20: 0.12885106 | AT20: 0.71187163 | AU20: 0.25081731 | AV20: 1 | AW20: 0 | AX20: 0 | AY20: 0 | AZ20: 0 | BA20: 10 | BB20: 242 | BC20: 256 | BD20: Pass
A21: HumanEval/19 | B21: humaneval | C21: 0 | D21: baseline_deterministic | E21: TRUE | F21: FALSE | G21: {'type': None} | H21: from typing import List def sort_numbers(numbers: str) -> str: """ Input is a space-delimited string of numberals from 'zero' to 'nine'. Valid choices are 'zero', 'one', 'two', 'three', 'four', 'five', 'six', 'seven', 'eight' and 'nine'. Return the string with numbers sorted from smallest to largest >>> sort_numbers('three one five') 'one three five' """ | I21: ```python from typing import List def sort_numbers(numbers: str) -> str: num_map = { 'zero': 0, 'one': 1, 'two': 2, 'three': 3, 'four': 4, 'five': 5, 'six': 6, 'seven': 7, 'eight': 8, 'nine': 9 } sorted_nums = sorted(numbers.split(), key=lambda x: num_map[x]) return ' '.join(sorted_nums) ``` | J21: from typing import List def sort_numbers(numbers: str) -> str: num_map = { 'zero': 0, 'one': 1, 'two': 2, 'three': 3, 'four': 4, 'five': 5, 'six': 6, 'seven': 7, 'eight': 8, 'nine': 9 } sorted_nums = sorted(numbers.split(), key=lambda x: num_map[x]) return ' '.join(sorted_nums) | K21: 113 | L21: 7.5590456 | M21: 0.086025933 | N21: 0.91721433 | O21: 9.9226171 | P21: 0.17471695 | S21: 113 | T21: 0.086025933 | U21: 0.21239367 | V21: 3.3003101e-07 | W21: 0.91721433 | X21: 0.917214 | Y21: 0.41920565 | Z21: 0.65598112 | AA21: 0.83461466 | AB21: 9.9226171 | AC21: 4.5376246 | AD21: 0.17471695 | AE21: 0.46812607 | AF21: 1.5764214 | AG21: 2.828125 | AH21: 11 | AI21: 0 | AJ21: 0 | AK21: 0 | AL21: 0.097345133 | AM21: 0 | AN21: 0 | AO21: 0 | AP21: 0 | AQ21: 1 | AR21: 2 | AS21: 0.11609596 | AT21: 0.91407106 | AU21: 0.25277163 | AV21: 2 | AW21: 0 | AX21: 0 | AY21: 0 | AZ21: 0 | BA21: 9 | BB21: 311 | BC21: 325 | BD21: Pass
A22: HumanEval/20 | B22: humaneval | C22: 0 | D22: baseline_deterministic | E22: TRUE | F22: FALSE | G22: {'type': None} | H22: from typing import List, Tuple def find_closest_elements(numbers: List[float]) -> Tuple[float, float]: """ From a supplied list of numbers (of length at least two) select and return two that are the closest to each other and return them in order (smaller number, larger number). >>> find_closest_elements([1.0, 2.0, 3.0, 4.0, 5.0, 2.2]) (2.0, 2.2) >>> find_closest_elements([1.0, 2.0, 3.0, 4.0, 5.0, 2.0]) (2.0, 2.0) """ | I22: ```python from typing import List, Tuple def find_closest_elements(numbers: List[float]) -> Tuple[float, float]: min_diff = float('inf') closest_pair = (0, 0) for i in range(len(numbers)): for j in range(i + 1, len(numbers)): diff = abs(numbers[i] - numbers[j]) if diff < min_diff: min_diff = diff closest_pair = (min(numbers[i], numbers[j]), max(numbers[i], numbers[j])) return closest_pair ``` | J22: from typing import List, Tuple def find_closest_elements(numbers: List[float]) -> Tuple[float, float]: min_diff = float('inf') closest_pair = (0, 0) for i in range(len(numbers)): for j in range(i + 1, len(numbers)): diff = abs(numbers[i] - numbers[j]) if diff < min_diff: min_diff = diff closest_pair = (min(numbers[i], numbers[j]), max(numbers[i], numbers[j])) return closest_pair | K22: 115 | L22: 7.7917848 | M22: 0.07255526 | N22: 1.6375015 | O22: 10.090848 | P22: 0.034090042 | S22: 115 | T22: 0.07255526 | U22: 0.24142157 | V22: 7.5282401e-07 | W22: 1.6375015 | X22: 1.6375007 | Y22: 0.18525973 | Z22: 0.478874 | AA22: 1.2110744 | AB22: 10.090848 | AC22: 4.1073718 | AD22: 0.034090042 | AE22: 0.10477245 | AF22: 2.0698864 | AG22: 3.565625 | AH22: 6 | AI22: 2 | AJ22: 1 | AK22: 0 | AL22: 0.052173913 | AM22: 0.017391304 | AN22: 0.0086956522 | AO22: 1 | AP22: 2 | AQ22: 3 | AR22: 3 | AS22: 0.10556124 | AT22: 1.6342661 | AU22: 0.2841678 | AV22: 3 | AW22: 1 | AX22: 1 | AY22: 0 | AZ22: 1 | BA22: 14 | BB22: 464 | BC22: 478 | BD22: Pass
A23: HumanEval/21 | B23: humaneval | C23: 0 | D23: baseline_deterministic | E23: TRUE | F23: FALSE | G23: {'type': None} | H23: from typing import List def rescale_to_unit(numbers: List[float]) -> List[float]: """ Given list of numbers (of at least two elements), apply a linear transform to that list, such that the smallest number will become 0 and the largest will become 1 >>> rescale_to_unit([1.0, 2.0, 3.0, 4.0, 5.0]) [0.0, 0.25, 0.5, 0.75, 1.0] """ | I23: ```python from typing import List def rescale_to_unit(numbers: List[float]) -> List[float]: min_val = min(numbers) max_val = max(numbers) range_val = max_val - min_val return [(x - min_val) / range_val for x in numbers] ``` | J23: from typing import List def rescale_to_unit(numbers: List[float]) -> List[float]: min_val = min(numbers) max_val = max(numbers) range_val = max_val - min_val return [(x - min_val) / range_val for x in numbers] | K23: 64 | L23: 4.3171888 | M23: 0.054877832 | N23: 0.86563802 | O23: 9.8304006 | P23: 0.59375 | S23: 64 | T23: 0.054877832 | U23: 0.15026429 | V23: 1.4166986e-06 | W23: 0.86563802 | X23: 0.8656366 | Y23: 0.18263842 | Z23: 0.33968135 | AA23: 0.71425777 | AB23: 9.8304006 | AC23: 4.1070188 | AD23: 0.59375 | AE23: 0.74140625 | AF23: 2.1844464 | AG23: 3.821875 | AH23: 2 | AI23: 0 | AJ23: 0 | AK23: 0 | AL23: 0.03125 | AM23: 0 | AN23: 0 | AO23: 0 | AP23: 0 | AQ23: 0 | AR23: 0 | AS23: 0.078247194 | AT23: 0.863307 | AU23: 0.17617476 | AV23: 1 | AW23: 0 | AX23: 0 | AY23: 0 | AZ23: 0 | BA23: 7 | BB23: 226 | BC23: 240 | BD23: Pass
A24: HumanEval/22 | B24: humaneval | C24: 0 | D24: baseline_deterministic | E24: TRUE | F24: FALSE | G24: {'type': None} | H24: from typing import List, Any def filter_integers(values: List[Any]) -> List[int]: """ Filter given list of any python values only for integers >>> filter_integers(['a', 3.14, 5]) [5] >>> filter_integers([1, 2, 3, 'abc', {}, []]) [1, 2, 3] """ | I24: ```python from typing import List, Any def filter_integers(values: List[Any]) -> List[int]: return [value for value in values if isinstance(value, int)] ``` | J24: from typing import List, Any def filter_integers(values: List[Any]) -> List[int]: return [value for value in values if isinstance(value, int)] | K24: 39 | L24: 2.5990736 | M24: 0.079726462 | N24: 1.0133976 | O24: 9.8098964 | P24: 1.015625 | S24: 39 | T24: 0.079726462 | U24: 0.21293487 | V24: 4.2340716e-06 | W24: 1.0133976 | X24: 1.0133933 | Y24: 0.37039073 | Z24: 0.47143123 | AA24: 0.87916374 | AB24: 9.8098964 | AC24: 4.3089547 | AD24: 1.015625 | AE24: 1.2671592 | AF24: 1.9946018 | AG24: 2.174147 | AH24: 2 | AI24: 1 | AJ24: 0 | AK24: 0 | AL24: 0.051282051 | AM24: 0.025641026 | AN24: 0 | AO24: 0 | AP24: 0 | AQ24: 0 | AR24: 0 | AS24: 0.14100312 | AT24: 1.0133016 | AU24: 0.30045944 | AV24: 1 | AW24: 1 | AX24: 0 | AY24: 0 | AZ24: 1 | BA24: 4 | BB24: 147 | BC24: 161 | BD24: Pass
... A27: HumanEval/25 | B27: humaneval | C27: 0 | D27: baseline_deterministic | E27: TRUE | F27: FALSE | G27: {'type': None} | H27: from typing import List def factorize(n: int) -> List[int]: """ Return list of prime factors of given integer in the order from smallest to largest. Each of the factors should be listed number of times corresponding to how many times it appeares in factorization. Input number should be equal to the product of all factors >>> factorize(8) [2, 2, 2] >>> factorize(25) [5, 5] >>> factorize(70) [2, 5, 7] """ | I27: ```python from typing import List def factorize(n: int) -> List[int]: factors = [] # Start with the smallest prime number divisor = 2 while n >= divisor * divisor: if n % divisor == 0: factors.append(divisor) n //= divisor else: divisor += 1 if n > 1: factors.append(n) return factors ``` | J27: from typing import List def factorize(n: int) -> List[int]: factors = [] # Start with the smallest prime number divisor = 2 while n >= divisor * divisor: if n % divisor == 0: factors.append(divisor) n //= divisor else: divisor += 1 if n > 1: factors.append(n) return factors | K27: 93 | L27: 6.2524025 | M27: 0.091157489 | N27: 0.95336765 | O27: 9.6115901 | P27: 0.34375 | S27: 93 | T27: 0.091157489 | U27: 0.21394158 | V27: 3.1760803e-07 | W27: 0.95336765 | X27: 0.95336733 | Y27: 0.39071323 | Z27: 0.62051871 | AA27: 0.880479 | AB27: 9.6115901 | AC27: 4.6142504 | AD27: 0.34375 | AE27: 0.40647743 | AF27: 1.3647724 | AG27: 2.1110794 | AH27: 6 | AI27: 0 | AJ27: 0 | AK27: 0 | AL27: 0.064516129 | AM27: 0 | AN27: 0 | AO27: 0 | AP27: 0 | AQ27: 0 | AR27: 2 | AS27: 0.12800035 | AT27: 0.95320905 | AU27: 0.26405606 | AV27: 2 | AW27: 0 | AX27: 0 | AY27: 0 | AZ27: 0 | BA27: 15 | BB27: 359 | BC27: 373 | BD27: Pass
A28: HumanEval/26 | B28: humaneval | C28: 0 | D28: baseline_deterministic | E28: FALSE | F28: TRUE | G28: {'type': 'RuntimeError', 'message': 'AssertionError', 'stderr_tail': 'Traceback (most recent call last):\n File "/tmp/tmp19cy781x/candidate_eval.py", line 38, in <module>\n check(remove_duplicates)\n File "/tmp/tmp19cy781x/candidate_eval.py", line 35, in check\n assert candidate([1, 2, 3, 2, 4, 3, 5]) == [1, 4, 5]\n ^^^^^^^^^^^^^^^^^^^^^^^^^^^^^^^^^^^^^^^^^^^^^\nAssertionError\n', 'stdout_tail': ''} | H28: from typing import List def remove_duplicates(numbers: List[int]) -> List[int]: """ From a list of integers, remove all elements that occur more than once. Keep order of elements left the same as in the input. >>> remove_duplicates([1, 2, 3, 2, 4]) [1, 3, 4] """ | I28: ```python from typing import List def remove_duplicates(numbers: List[int]) -> List[int]: seen = set() result = [] for number in numbers: if number not in seen: seen.add(number) result.append(number) return result ``` | J28: from typing import List def remove_duplicates(numbers: List[int]) -> List[int]: seen = set() result = [] for number in numbers: if number not in seen: seen.add(number) result.append(number) return result | K28: 58 | L28: 3.849392 | M28: 0.095749479 | N28: 0.85007972 | O28: 9.0041393 | P28: 0.0625 | Q28: RuntimeError | R28: AssertionError | S28: 58 | T28: 0.095749479 | U28: 0.21142318 | V28: 1.1030898e-05 | W28: 0.85007972 | X28: 0.85006868 | Y28: 0.44484966 | Z28: 0.66729122 | AA28: 0.74949284 | AB28: 9.0041393 | AC28: 4.5478772 | AD28: 0.0625 | AE28: 0.28515625 | AF28: 0.86235819 | AG28: 1.9255693 | AH28: 6 | AI28: 0 | AJ28: 0 | AK28: 0 | AL28: 0.10344828 | AM28: 0 | AN28: 0 | AO28: 0 | AP28: 1 | AQ28: 1 | AR28: 2 | AS28: 0.14272344 | AT28: 0.84739412 | AU28: 0.27482785 | AV28: 2 | AW28: 0 | AX28: 0 | AY28: 0 | AZ28: 0 | BA28: 10 | BB28: 252 | BC28: 266 | BD28: Other_fail
A29: HumanEval/27 | B29: humaneval | C29: 0 | D29: baseline_deterministic | E29: TRUE | F29: FALSE | G29: {'type': None} | H29: def flip_case(string: str) -> str: """ For a given string, flip lowercase characters to uppercase and uppercase to lowercase. >>> flip_case('Hello') 'hELLO' """ | I29: ```python def flip_case(s: str) -> str: return ''.join(c.lower() if c.isupper() else c.upper() for c in s) ``` | J29: def flip_case(s: str) -> str: return ''.join(c.lower() if c.isupper() else c.upper() for c in s) | K29: 36 | L29: 2.3751137 | M29: 0.12269943 | N29: 0.85456485 | O29: 9.1444329 | P29: 0.28125 | S29: 36 | T29: 0.12269943 | U29: 0.26102633 | V29: 1.4218094e-06 | W29: 0.85456485 | X29: 0.85456342 | Y29: 0.64363411 | Z29: 0.72063161 | AA29: 0.80961134 | AB29: 9.1444329 | AC29: 4.8606752 | AD29: 0.28125 | AE29: 0.28373604 | AF29: 0.67613745 | AG29: 1.1044025 | AH29: 6 | AI29: 0 | AJ29: 0 | AK29: 0 | AL29: 0.16666667 | AM29: 0 | AN29: 0 | AO29: 0 | AP29: 0 | AQ29: 0 | AR29: 2 | AS29: 0.17747339 | AT29: 0.85096429 | AU29: 0.33725469 | AV29: 2 | AW29: 0 | AX29: 0 | AY29: 0 | AZ29: 0 | BA29: 2 | BB29: 100 | BC29: 114 | BD29: Pass
A30: HumanEval/28 | B30: humaneval | C30: 0 | D30: baseline_deterministic | E30: TRUE | F30: FALSE | G30: {'type': None} | H30: from typing import List def concatenate(strings: List[str]) -> str: """ Concatenate list of strings into a single string >>> concatenate([]) '' >>> concatenate(['a', 'b', 'c']) 'abc' """ | I30: ```python from typing import List def concatenate(strings: List[str]) -> str: return ''.join(strings) ``` | J30: from typing import List def concatenate(strings: List[str]) -> str: return ''.join(strings) | K30: 26 | L30: 1.7258971 | M30: 0.11078547 | N30: 0.67998892 | O30: 8.3762842 | P30: 0.51704407 | S30: 26 | T30: 0.11078547 | U30: 0.22453606 | V30: 2.1573545e-05 | W30: 0.67998892 | X30: 0.67996735 | Y30: 0.49647652 | Z30: 0.64747609 | AA30: 0.67767958 | AB30: 8.3762842 | AC30: 4.2347439 | AD30: 0.51704407 | AE30: 0.65766907 | AF30: 1.2198143 | AG30: 1.8629265 | AH30: 3 | AI30: 0 | AJ30: 0 | AK30: 0 | AL30: 0.11538462 | AM30: 0 | AN30: 0 | AO30: 0 | AP30: 0 | AQ30: 0 | AR30: 0 | AS30: 0.162529 | AT30: 0.67747988 | AU30: 0.2877524 | AV30: 1 | AW30: 0 | AX30: 0 | AY30: 0 | AZ30: 0 | BA30: 4 | BB30: 96 | BC30: 110 | BD30: Pass
A31: HumanEval/29 | B31: humaneval | C31: 0 | D31: baseline_deterministic | E31: TRUE | F31: FALSE | G31: {'type': None} | H31: from typing import List def filter_by_prefix(strings: List[str], prefix: str) -> List[str]: """ Filter an input list of strings only for ones that start with a given prefix. >>> filter_by_prefix([], 'a') [] >>> filter_by_prefix(['abc', 'bcd', 'cde', 'array'], 'a') ['abc', 'array'] """ | I31: ```python from typing import List def filter_by_prefix(strings: List[str], prefix: str) -> List[str]: return [s for s in strings if s.startswith(prefix)] ``` | J31: from typing import List def filter_by_prefix(strings: List[str], prefix: str) -> List[str]: return [s for s in strings if s.startswith(prefix)] | K31: 40 | L31: 2.6662786 | M31: 0.063788903 | N31: 0.57557309 | O31: 9.7725857 | P31: 1.3096581 | S31: 40 | T31: 0.063788903 | U31: 0.16276266 | V31: 3.8453531e-06 | W31: 0.57557309 | X31: 0.57556924 | Y31: 0.34097829 | Z31: 0.49550651 | AA31: 0.55665655 | AB31: 9.7725857 | AC31: 3.9480326 | AD31: 1.3096581 | AE31: 1.5146303 | AF31: 2.0511364 | AG31: 2.3180397 | AH31: 2 | AI31: 0 | AJ31: 0 | AK31: 0 | AL31: 0.05 | AM31: 0 | AN31: 0 | AO31: 0 | AP31: 0 | AQ31: 0 | AR31: 0 | AS31: 0.085455864 | AT31: 0.57295293 | AU31: 0.19379254 | AV31: 1 | AW31: 0 | AX31: 0 | AY31: 0 | AZ31: 0 | BA31: 4 | BB31: 148 | BC31: 162 | BD31: Pass
A32: HumanEval/30 | B32: humaneval | C32: 0 | D32: baseline_deterministic | E32: TRUE | F32: FALSE | G32: {'type': None} | H32: def get_positive(l: list): """Return only positive numbers in the list. >>> get_positive([-1, 2, -4, 5, 6]) [2, 5, 6] >>> get_positive([5, 3, -5, 2, -3, 3, 9, 0, 123, 1, -10]) [5, 3, 2, 3, 9, 123, 1] """ | I32: ```python def get_positive(l: list): return [x for x in l if x > 0] ``` | J32: def get_positive(l: list): return [x for x in l if x > 0] | K32: 26 | L32: 1.7924185 | M32: 0.08807022 | N32: 0.75417536 | O32: 9.1380032 | P32: 1.311079 | S32: 26 | T32: 0.08807022 | U32: 0.1936535 | V32: 3.0990977e-06 | W32: 0.75417536 | X32: 0.75417227 | Y32: 0.3970806 | Z32: 0.46841846 | AA32: 0.68825643 | AB32: 9.1380032 | AC32: 4.8803221 | AD32: 1.311079 | AE32: 1.3554688 | AF32: 1.6519899 | AG32: 2.211648 | AH32: 1 | AI32: 0 | AJ32: 0 | AK32: 0 | AL32: 0.038461538 | AM32: 0 | AN32: 0 | AO32: 0 | AP32: 0 | AQ32: 0 | AR32: 0 | AS32: 0.14586481 | AT32: 0.75150501 | AU32: 0.25733167 | AV32: 1 | AW32: 0 | AX32: 0 | AY32: 0 | AZ32: 0 | BA32: 2 | BB32: 61 | BC32: 75 | BD32: Pass
A33: HumanEval/31 | B33: humaneval | C33: 0 | D33: baseline_deterministic | E33: TRUE | F33: FALSE | G33: {'type': None} | H33: def is_prime(n): """Return true if a given number is prime, and false otherwise. >>> is_prime(6) False >>> is_prime(101) True >>> is_prime(11) True >>> is_prime(13441) True >>> is_prime(61) True >>> is_prime(4) False >>> is_prime(1) False """ | I33: ```python def is_prime(n): if n <= 1: return False if n == 2: return True if n % 2 == 0: return False for i in range(3, int(n**0.5) + 1, 2): if n % i == 0: return False return True ``` | J33: def is_prime(n): if n <= 1: return False if n == 2: return True if n % 2 == 0: return False for i in range(3, int(n**0.5) + 1, 2): if n % i == 0: return False return True | K33: 85 | L33: 5.6882757 | M33: 0.048263938 | N33: 0.81192708 | O33: 10.666695 | P33: 0.008523941 | S33: 85 | T33: 0.048263938 | U33: 0.16232513 | V33: 2.1395573e-07 | W33: 0.81192708 | X33: 0.81192687 | Y33: 0.077408677 | Z33: 0.42387022 | AA33: 0.78855043 | AB33: 10.666695 | AC33: 4.1299988 | AD33: 0.008523941 | AE33: 0.080113831 | AF33: 2.5002838 | AG33: 4.2125 | AH33: 4 | AI33: 0 | AJ33: 0 | AK33: 0 | AL33: 0.047058824 | AM33: 0 | AN33: 0 | AO33: 1 | AP33: 2 | AQ33: 2 | AR33: 3 | AS33: 0.08807925 | AT33: 0.81101982 | AU33: 0.22959848 | AV33: 1 | AW33: 0 | AX33: 0 | AY33: 0 | AZ33: 0 | BA33: 11 | BB33: 234 | BC33: 248 | BD33: Pass
A34: HumanEval/32 | B34: humaneval | C34: 0 | D34: baseline_deterministic | E34: FALSE | F34: TRUE | G34: {'type': 'RuntimeError', 'message': "NameError: name 'poly' is not defined", 'stderr_tail': 'Traceback (most recent call last):\n File "/tmp/tmpxsor970t/candidate_eval.py", line 64, in <module>\n check(find_zero)\n File "/tmp/tmpxsor970t/candidate_eval.py", line 59, in check\n solution = candidate(copy.deepcopy(coeffs))\n ^^^^^^^^^^^^^^^^^^^^^^^^^^^^^^^^\n File "/tmp/tmpxsor970t/candidate_eval.py", line 35, in find_zero\n fx = f(x)\n ^^^^\n File "/tmp/tmpxsor970t/candidate_eval.py", line 28, in f\n return poly(xs, x)\n ^^^^\nNameError: name \'poly\' is not defined\n', 'stdout_tail': ''} | H34: import math def poly(xs: list, x: float): """ Evaluates polynomial with coefficients xs at point x. return xs[0] + xs[1] * x + xs[1] * x^2 + .... xs[n] * x^n """ return sum([coeff * math.pow(x, i) for i, coeff in enumerate(xs)]) def find_zero(xs: list): """ xs are coefficients of a polynomial. find_zero find x such that poly(x) = 0. find_zero returns only only zero point, even if there are many. Moreover, find_zero only takes list xs having even number of coefficients and largest non zero coefficient as it guarantees a solution. >>> round(find_zero([1, 2]), 2) # f(x) = 1 + 2x -0.5 >>> round(find_zero([-6, 11, -6, 1]), 2) # (x - 1) * (x - 2) * (x - 3) = -6 + 11x - 6x^2 + x^3 1.0 """ | I34: ```python import math def poly(xs: list, x: float): """ Evaluates polynomial with coefficients xs at point x. return xs[0] + xs[1] * x + xs[1] * x^2 + .... xs[n] * x^n """ return sum([coeff * math.pow(x, i) for i, coeff in enumerate(xs)]) def find_zero(xs: list): """ xs are coefficients of a polynomial. find_zero find x such that poly(x) = 0. find_zero returns only one zero point, even if there are many. Moreover, find_zero only takes list xs having even number of coefficients and largest non zero coefficient as it guarantees a solution. >>> round(find_zero([1, 2]), 2) # f(x) = 1 + 2x -0.5 >>> round(find_zero([-6, 11, -6, 1]), 2) # (x - 1) * (x - 2) * (x - 3) = -6 + 11x - 6x^2 + x^3 1.0 """ def f(x): return poly(xs, x) def df(x): return sum([i * coeff * math.pow(x, i-1) for i, coeff in enumerate(xs) if i > 0]) x = 0.0 while True: fx = f(x) dfx = df(x) if abs(fx) < 1e-9: return round(x, 2) x -= fx / dfx ``` | J34: import math def find_zero(xs: list): """ xs are coefficients of a polynomial. find_zero find x such that poly(x) = 0. find_zero returns only one zero point, even if there are many. Moreover, find_zero only takes list xs having even number of coefficients and largest non zero coefficient as it guarantees a solution. >>> round(find_zero([1, 2]), 2) # f(x) = 1 + 2x -0.5 >>> round(find_zero([-6, 11, -6, 1]), 2) # (x - 1) * (x - 2) * (x - 3) = -6 + 11x - 6x^2 + x^3 1.0 """ def f(x): return poly(xs, x) def df(x): return sum([i * coeff * math.pow(x, i-1) for i, coeff in enumerate(xs) if i > 0]) x = 0.0 while True: fx = f(x) dfx = df(x) if abs(fx) < 1e-9: return round(x, 2) x -= fx / dfx | K34: 362 | L34: 25.283828 | M34: 0.083161052 | N34: 2.336978 | O34: 9.4989352 | P34: 0.071022034 | Q34: RuntimeError | R34: NameError: name 'poly' is not defined | S34: 362 | T34: 0.083161052 | U34: 0.26180888 | V34: 7.0414371e-06 | W34: 2.336978 | X34: 2.3369709 | Y34: 0.23088876 | Z34: 0.5616143 | AA34: 1.168433 | AB34: 9.4989352 | AC34: 3.7698352 | AD34: 0.071022034 | AE34: 0.27190445 | AF34: 1.7596591 | AG34: 2.962359 | AH34: 20 | AI34: 6 | AJ34: 3 | AK34: 2 | AL34: 0.055248619 | AM34: 0.016574586 | AN34: 0.0082872928 | AO34: 0 | AP34: 2 | AQ34: 3 | AR34: 6 | AS34: 0.1175689 | AT34: 2.1143666 | AU34: 0.30556336 | AV34: 2 | AW34: 2 | AX34: 2 | AY34: 0 | AZ34: 2 | BA34: 27 | BB34: 819 | BC34: 1071 | BD34: Other_fail
A35: HumanEval/33 | B35: humaneval | C35: 0 | D35: baseline_deterministic | E35: TRUE | F35: FALSE | G35: {'type': None} | H35: def sort_third(l: list): """This function takes a list l and returns a list l' such that l' is identical to l in the indicies that are not divisible by three, while its values at the indicies that are divisible by three are equal to the values of the corresponding indicies of l, but sorted. >>> sort_third([1, 2, 3]) [1, 2, 3] >>> sort_third([5, 6, 3, 4, 8, 9, 2]) [2, 6, 3, 4, 8, 9, 5] """ | I35: ```python def sort_third(l: list): indices_divisible_by_three = [i for i in range(len(l)) if i % 3 == 0] values_at_divisible_indices = [l[i] for i in indices_divisible_by_three] sorted_values = sorted(values_at_divisible_indices) result = l[:] for original_index, new_value in zip(indices_divisible_by_three, sorted_values): result[original_index] = new_value return result ``` | J35: def sort_third(l: list): indices_divisible_by_three = [i for i in range(len(l)) if i % 3 == 0] values_at_divisible_indices = [l[i] for i in indices_divisible_by_three] sorted_values = sorted(values_at_divisible_indices) result = l[:] for original_index, new_value in zip(indices_divisible_by_three, sorted_values): result[original_index] = new_value return result | K35: 106 | L35: 7.1675835 | M35: 0.12921516 | N35: 1.4562602 | O35: 8.5394581 | P35: 0.11363602 | S35: 106 | T35: 0.12921516 | U35: 0.28515995 | V35: 6.4578398e-06 | W35: 1.4562602 | X35: 1.4562537 | Y35: 0.5048719 | Z35: 0.76363908 | AA35: 1.4099303 | AB35: 8.5394581 | AC35: 4.4129994 | AD35: 0.11363602 | AE35: 0.45994186 | AF35: 1.1977983 | AG35: 1.903409 | AH35: 12 | AI35: 3 | AJ35: 0 | AK35: 0 | AL35: 0.11320755 | AM35: 0.028301887 | AN35: 0 | AO35: 0 | AP35: 0 | AQ35: 1 | AR35: 2 | AS35: 0.18460367 | AT35: 1.4541378 | AU35: 0.35238871 | AV35: 2 | AW35: 1 | AX35: 0 | AY35: 0 | AZ35: 1 | BA35: 10 | BB35: 405 | BC35: 419 | BD35: Pass
A36: HumanEval/34 | B36: humaneval | C36: 0 | D36: baseline_deterministic | E36: TRUE | F36: FALSE | G36: {'type': None} | H36: def unique(l: list): """Return sorted unique elements in a list >>> unique([5, 3, 5, 2, 3, 3, 9, 0, 123]) [0, 2, 3, 5, 9, 123] """ | I36: ```python def unique(l: list): return sorted(set(l)) ``` | J36: def unique(l: list): return sorted(set(l)) | K36: 17 | L36: 1.144213 | M36: 0.15227317 | N36: 1.1309569 | O36: 6.5330469 | P36: 0.96875 | S36: 17 | T36: 0.15227317 | U36: 0.31421392 | V36: 0.00052845303 | W36: 1.1309569 | X36: 1.1304284 | Y36: 0.46468173 | Z36: 0.83162274 | AA36: 1.0710901 | AB36: 6.5330469 | AC36: 3.3531414 | AD36: 0.96875 | AE36: 1.1267047 | AF36: 1.7585236 | AG36: 2.3156261 | AH36: 2 | AI36: 1 | AJ36: 0 | AK36: 0 | AL36: 0.11764706 | AM36: 0.058823529 | AN36: 0 | AO36: 0 | AP36: 0 | AQ36: 0 | AR36: 0 | AS36: 0.23981391 | AT36: 1.128298 | AU36: 0.39920977 | AV36: 1 | AW36: 1 | AX36: 0 | AY36: 0 | AZ36: 1 | BA36: 2 | BB36: 46 | BC36: 60 | BD36: Pass
A37: HumanEval/35 | B37: humaneval | C37: 0 | D37: baseline_deterministic | E37: TRUE | F37: FALSE | G37: {'type': None} | H37: def max_element(l: list): """Return maximum element in the list. >>> max_element([1, 2, 3]) 3 >>> max_element([5, 3, -5, 2, -3, 3, 9, 0, 123, 1, -10]) 123 """ | I37: ```python def max_element(l: list): return max(l) ``` | J37: def max_element(l: list): return max(l) | K37: 17 | L37: 1.1417257 | M37: 0.11726695 | N37: 0.72614503 | O37: 6.8645141 | P37: 1.110796 | S37: 17 | T37: 0.11726695 | U37: 0.23507182 | V37: 0.00036014165 | W37: 0.72614503 | X37: 0.72578489 | Y37: 0.41467616 | Z37: 0.70914159 | AA37: 0.72274434 | AB37: 6.8645141 | AC37: 3.2513252 | AD37: 1.110796 | AE37: 1.1957957 | AF37: 1.5357944 | AG37: 2.3656254 | AH37: 2 | AI37: 0 | AJ37: 0 | AK37: 0 | AL37: 0.11764706 | AM37: 0 | AN37: 0 | AO37: 0 | AP37: 0 | AQ37: 0 | AR37: 0 | AS37: 0.19417843 | AT37: 0.72578489 | AU37: 0.32424166 | AV37: 1 | AW37: 0 | AX37: 0 | AY37: 0 | AZ37: 0 | BA37: 2 | BB37: 43 | BC37: 57 | BD37: Pass
A38: HumanEval/36 | B38: humaneval | C38: 0 | D38: baseline_deterministic | E38: TRUE | F38: FALSE | G38: {'type': None} | H38: def fizz_buzz(n: int): """Return the number of times the digit 7 appears in integers less than n which are divisible by 11 or 13. >>> fizz_buzz(50) 0 >>> fizz_buzz(78) 2 >>> fizz_buzz(79) 3 """ | I38: ```python def fizz_buzz(n: int) -> int: count = 0 for i in range(1, n): if i % 11 == 0 or i % 13 == 0: count += str(i).count('7') return count ``` | J38: def fizz_buzz(n: int) -> int: count = 0 for i in range(1, n): if i % 11 == 0 or i % 13 == 0: count += str(i).count('7') return count | K38: 66 | L38: 4.3635583 | M38: 0.038003535 | N38: 0.68949258 | O38: 10.730361 | P38: 0.26988602 | S38: 66 | T38: 0.038003535 | U38: 0.12724004 | V38: 3.3547344e-06 | W38: 0.68949258 | X38: 0.68948923 | Y38: 0.082691967 | Z38: 0.18935733 | AA38: 0.68814832 | AB38: 10.730361 | AC38: 4.0119729 | AD38: 0.26988602 | AE38: 0.32805386 | AF38: 3.0433254 | AG38: 4.580965 | AH38: 2 | AI38: 0 | AJ38: 0 | AK38: 0 | AL38: 0.03030303 | AM38: 0 | AN38: 0 | AO38: 0 | AP38: 0 | AQ38: 0 | AR38: 2 | AS38: 0.070345899 | AT38: 0.68870476 | AU38: 0.18279678 | AV38: 1 | AW38: 0 | AX38: 0 | AY38: 0 | AZ38: 0 | BA38: 6 | BB38: 164 | BC38: 178 | BD38: Pass
A39: HumanEval/37 | B39: humaneval | C39: 0 | D39: baseline_deterministic | E39: TRUE | F39: FALSE | G39: {'type': None} | H39: def sort_even(l: list): """This function takes a list l and returns a list l' such that l' is identical to l in the odd indicies, while its values at the even indicies are equal to the values of the even indicies of l, but sorted. >>> sort_even([1, 2, 3]) [1, 2, 3] >>> sort_even([5, 6, 3, 4]) [3, 6, 5, 4] """ | I39: ```python def sort_even(l: list): even_indices = [i for i in range(len(l)) if i % 2 == 0] even_values = sorted([l[i] for i in even_indices]) result = l[:] for i, value in zip(even_indices, even_values): result[i] = value return result ``` | J39: def sort_even(l: list): even_indices = [i for i in range(len(l)) if i % 2 == 0] even_values = sorted([l[i] for i in even_indices]) result = l[:] for i, value in zip(even_indices, even_values): result[i] = value return result | K39: 79 | L39: 5.3119225 | M39: 0.16161123 | N39: 1.6868722 | O39: 8.68964 | P39: 0.27556801 | S39: 79 | T39: 0.16161123 | U39: 0.32390775 | V39: 2.8860941e-06 | W39: 1.6868722 | X39: 1.6868694 | Y39: 0.62350346 | Z39: 0.70489838 | AA39: 1.4312887 | AB39: 8.68964 | AC39: 4.8471416 | AD39: 0.27556801 | AE39: 0.41406246 | AF39: 1.0897724 | AG39: 1.5340912 | AH39: 13 | AI39: 2 | AJ39: 1 | AK39: 0 | AL39: 0.16455696 | AM39: 0.025316456 | AN39: 0.012658228 | AO39: 0 | AP39: 0 | AQ39: 0 | AR39: 2 | AS39: 0.23206365 | AT39: 1.6718307 | AU39: 0.4302976 | AV39: 4 | AW39: 1 | AX39: 1 | AY39: 0 | AZ39: 1 | BA39: 7 | BB39: 252 | BC39: 266 | BD39: Pass
