Workbook

Sheet Metodología
A1: Cómo leer esta validación
A3: Elemento | B3: Definición | C3: Interpretación
A4: Baseline greedy | B4: El modelo elige top-1 en cada paso. | C4: Los 20 problemas incluidos fallaron con este baseline.
A5: Rama top-2 | B5: Se mantiene el prefijo, se fuerza top-2 en una posición y se continúa greedy. | C5: Una rama PASS constituye una recuperación local contrafactual.
A6: Lookahead | B6: Continuación corta de 12 tokens para todas las posiciones elegibles. | C6: Sirve para ordenar; no determina por sí mismo si el programa pasa.
A7: Presupuesto k | B7: Cantidad máxima de ramas completas por problema. | C7: Todos los selectores se comparan con el mismo k.
A8: Problema recuperado | B8: Al menos una rama seleccionada pasó los tests base. | C8: Es la métrica primaria por problema.
A9: Precisión de rama | B9: Ramas PASS / ramas nominales seleccionadas. | C9: Mide densidad de ramas útiles, no cobertura del oracle.
A10: No evaluada completa | B10: La posición tiene lookahead pero no rama completa. | C10: No debe interpretarse como FAIL.
A11: Límite | B11: No se completaron todas las 1.649 posiciones ni se ejecutó HumanEval+. | C11: Todavía no conocemos el oracle exhaustivo ni la robustez reforzada.
A13: Fuentes reproducibles
A14: Archivo | B14: Contenido | C14: Ruta de origen
A15: validation_report.json | B15: Configuración y resultados agregados | C15: frozen_selector_validation_checkpoint (1).zip
A16: branches.jsonl | B16: 255 ramas completas únicas | C16: frozen_selector_validation_checkpoint (1).zip
A17: lookaheads.jsonl | B17: 1.649 posiciones con continuación corta | C17: frozen_selector_validation_checkpoint (1).zip

Sheet Resumen
A1: Validación de branching adaptativo — 20 problemas
A2: Qwen2.5-Coder-7B · HumanEval/26 excluido por desarrollo · tests base de HumanEval | J2: Selector | K2: Problemas recuperados
J3: =A9 -> Semántico | K3: =B9 -> 10
A4: Problemas | C4: Lookaheads cortos | E4: Ramas completas | G4: Posiciones sin rama completa | J4: =A10 -> Entropía | K4: =B10 -> 10
A5: =COUNTA(Problemas!$A$2:$A$21) -> 20 | C5: =COUNTA(Lookaheads!$A$2:$A$1650) -> 1649 | E5: =COUNTA(Ramas!$A$2:$A$256) -> 255 | G5: =C5-E5 -> 1394 | J5: =A11 -> Margen | K5: =B11 -> 10
J6: =A12 -> Aleatorio | K6: =B12 -> 6
A8: Selector | B8: Problemas recuperados | C8: Tasa | D8: Ramas PASS | E8: Ramas nominales | F8: Precisión de rama | G8: Brecha vs random | H8: Lectura
A9: Semántico | B9: =SUM(Problemas!$B$2:$B$21) -> 10 | C9: =B9/$A$5 -> 0.5 | D9: =SUMPRODUCT(Ramas!$I$2:$I$256,Ramas!$H$2:$H$256) -> 15 | E9: =SUM(Ramas!$I$2:$I$256) -> 100 | F9: =IFERROR(D9/E9,0) -> 0.15 | G9: =B9-$B$12 -> 4 | H9: Complementario, pero no superior a entropía
A10: Entropía | B10: =SUM(Problemas!$C$2:$C$21) -> 10 | C10: =B10/$A$5 -> 0.5 | D10: =SUMPRODUCT(Ramas!$J$2:$J$256,Ramas!$H$2:$H$256) -> 21 | E10: =SUM(Ramas!$J$2:$J$256) -> 100 | F10: =IFERROR(D10/E10,0) -> 0.21 | G10: =B10-$B$12 -> 4 | H10: Mejor con presupuestos pequeños
A11: Margen | B11: =SUM(Problemas!$D$2:$D$21) -> 10 | C11: =B11/$A$5 -> 0.5 | D11: =SUMPRODUCT(Ramas!$K$2:$K$256,Ramas!$H$2:$H$256) -> 21 | E11: =SUM(Ramas!$K$2:$K$256) -> 100 | F11: =IFERROR(D11/E11,0) -> 0.21 | G11: =B11-$B$12 -> 4 | H11: Casi redundante con entropía
A12: Aleatorio | B12: =SUM(Problemas!$E$2:$E$21) -> 6 | C12: =B12/$A$5 -> 0.3 | D12: =SUMPRODUCT(Ramas!$L$2:$L$256,Ramas!$H$2:$H$256) -> 7 | E12: =SUM(Ramas!$L$2:$L$256) -> 100 | F12: =IFERROR(D12/E12,0) -> 0.07 | G12: =B12-$B$12 -> 0 | H12: Control de referencia
A15: Conclusión defendible
A16: Cambiar una decisión top-1 por top-2 recuperó 10 de 20 problemas con cinco ramas. El selector semántico superó al control aleatorio, pero empató con entropía y margen. Su valor potencial es aportar trayectorias diferentes para una política híbrida.
J20: Selector | K20: PASS | L20: FAIL
J21: =A9 -> Semántico | K21: =D9 -> 15 | L21: =E9-D9 -> 85
J22: =A10 -> Entropía | K22: =D10 -> 21 | L22: =E10-D10 -> 79
J23: =A11 -> Margen | K23: =D11 -> 21 | L23: =E11-D11 -> 79
J24: =A12 -> Aleatorio | K24: =D12 -> 7 | L24: =E12-D12 -> 93

Sheet Presupuesto
A1: task_id | B1: selector | C1: rank | D1: position | E1: branch_passed | F1: recovered_within_k | H1: Ramas permitidas | I1: Semántico | J1: Entropía | K1: Margen | L1: Aleatorio | N1: Ramas permitidas | O1: Semántico | P1: Entropía | Q1: Margen | R1: Aleatorio
A2: HumanEval/140 | B2: Semántico | C2: 1 | D2: 6 | E2: 1 | F2: 1 | H2: 1 | I2: 5 | J2: 8 | K2: 6 | L2: 4 | N2: =H2 -> 1 | O2: =I2/20 -> 0.25 | P2: =J2/20 -> 0.4 | Q2: =K2/20 -> 0.3 | R2: =L2/20 -> 0.2
A3: HumanEval/140 | B3: Semántico | C3: 2 | D3: 8 | E3: 0 | F3: 1 | H3: 2 | I3: 7 | J3: 10 | K3: 8 | L3: 5 | N3: =H3 -> 2 | O3: =I3/20 -> 0.35 | P3: =J3/20 -> 0.5 | Q3: =K3/20 -> 0.4 | R3: =L3/20 -> 0.25
A4: HumanEval/140 | B4: Semántico | C4: 3 | D4: 7 | E4: 1 | F4: 1 | H4: 3 | I4: 7 | J4: 10 | K4: 10 | L4: 6 | N4: =H4 -> 3 | O4: =I4/20 -> 0.35 | P4: =J4/20 -> 0.5 | Q4: =K4/20 -> 0.5 | R4: =L4/20 -> 0.3
A5: HumanEval/140 | B5: Semántico | C5: 4 | D5: 4 | E5: 0 | F5: 1 | H5: 4 | I5: 8 | J5: 10 | K5: 10 | L5: 6 | N5: =H5 -> 4 | O5: =I5/20 -> 0.4 | P5: =J5/20 -> 0.5 | Q5: =K5/20 -> 0.5 | R5: =L5/20 -> 0.3 | T5: score | U5: 10
A6: HumanEval/140 | B6: Semántico | C6: 5 | D6: 3 | E6: 0 | F6: 1 | H6: 5 | I6: 10 | J6: 10 | K6: 10 | L6: 6 | N6: =H6 -> 5 | O6: =I6/20 -> 0.5 | P6: =J6/20 -> 0.5 | Q6: =K6/20 -> 0.5 | R6: =L6/20 -> 0.3
A7: HumanEval/140 | B7: Entropía | C7: 1 | D7: 7 | E7: 1 | F7: 1
A8: HumanEval/140 | B8: Entropía | C8: 2 | D8: 6 | E8: 1 | F8: 1
A9: HumanEval/140 | B9: Entropía | C9: 3 | D9: 4 | E9: 0 | F9: 1 | T9: Pasas: | W9: Nota
A10: HumanEval/140 | B10: Entropía | C10: 4 | D10: 5 | E10: 0 | F10: 1 | T10: l0 | W10: 7 | Y10: Asigno 7
A11: HumanEval/140 | B11: Entropía | C11: 5 | D11: 8 | E11: 0 | F11: 1 | T11: l1 | W11: 8
A12: HumanEval/140 | B12: Margen | C12: 1 | D12: 7 | E12: 1 | F12: 1 | T12: l2 | W12: 7
A13: HumanEval/140 | B13: Margen | C13: 2 | D13: 6 | E13: 1 | F13: 1 | T13: l3 | W13: 7
A14: HumanEval/140 | B14: Margen | C14: 3 | D14: 4 | E14: 0 | F14: 1 | T14: l | W14: 7
A15: HumanEval/140 | B15: Margen | C15: 4 | D15: 5 | E15: 0 | F15: 1
A16: HumanEval/140 | B16: Margen | C16: 5 | D16: 8 | E16: 0 | F16: 1
A17: HumanEval/140 | B17: Aleatorio | C17: 1 | D17: 2 | E17: 0 | F17: 0
A18: HumanEval/140 | B18: Aleatorio | C18: 2 | D18: 6 | E18: 1 | F18: 1
A19: HumanEval/140 | B19: Aleatorio | C19: 3 | D19: 7 | E19: 1 | F19: 1
A20: HumanEval/140 | B20: Aleatorio | C20: 4 | D20: 8 | E20: 0 | F20: 1
A21: HumanEval/140 | B21: Aleatorio | C21: 5 | D21: 9 | E21: 0 | F21: 1
A22: HumanEval/93 | B22: Semántico | C22: 1 | D22: 62 | E22: 0 | F22: 0
A23: HumanEval/93 | B23: Semántico | C23: 2 | D23: 50 | E23: 0 | F23: 0
A24: HumanEval/93 | B24: Semántico | C24: 3 | D24: 58 | E24: 0 | F24: 0
A25: HumanEval/93 | B25: Semántico | C25: 4 | D25: 64 | E25: 0 | F25: 0
A26: HumanEval/93 | B26: Semántico | C26: 5 | D26: 65 | E26: 0 | F26: 0
... A401: HumanEval/95 | B401: Aleatorio | C401: 5 | D401: 56 | E401: 0 | F401: 1

Sheet Problemas
A1: task_id | B1: Semántico | C1: Entropía | D1: Margen | E1: Aleatorio | F1: Nº selectores | G1: Consenso | H1: Semántico exclusivo | I1: Entropía exclusiva
A2: HumanEval/140 | B2: 1 | C2: 1 | D2: 1 | E2: 1 | F2: =SUM(B2:E2) -> 4 | G2: =IF(F2=0,"Sin recuperación",IF(F2=4,"Robusto",IF(F2=1,"Exclusivo","Compartido"))) -> Robusto | H2: =--AND(B2=1,C2=0) -> 0 | I2: =--AND(B2=0,C2=1) -> 0
A3: HumanEval/93 | B3: 0 | C3: 0 | D3: 0 | E3: 0 | F3: =SUM(B3:E3) -> 0 | G3: =IF(F3=0,"Sin recuperación",IF(F3=4,"Robusto",IF(F3=1,"Exclusivo","Compartido"))) -> Sin recuperación | H3: =--AND(B3=1,C3=0) -> 0 | I3: =--AND(B3=0,C3=1) -> 0
A4: HumanEval/10 | B4: 0 | C4: 0 | D4: 0 | E4: 0 | F4: =SUM(B4:E4) -> 0 | G4: =IF(F4=0,"Sin recuperación",IF(F4=4,"Robusto",IF(F4=1,"Exclusivo","Compartido"))) -> Sin recuperación | H4: =--AND(B4=1,C4=0) -> 0 | I4: =--AND(B4=0,C4=1) -> 0
A5: HumanEval/77 | B5: 1 | C5: 1 | D5: 1 | E5: 1 | F5: =SUM(B5:E5) -> 4 | G5: =IF(F5=0,"Sin recuperación",IF(F5=4,"Robusto",IF(F5=1,"Exclusivo","Compartido"))) -> Robusto | H5: =--AND(B5=1,C5=0) -> 0 | I5: =--AND(B5=0,C5=1) -> 0
A6: HumanEval/141 | B6: 1 | C6: 1 | D6: 1 | E6: 0 | F6: =SUM(B6:E6) -> 3 | G6: =IF(F6=0,"Sin recuperación",IF(F6=4,"Robusto",IF(F6=1,"Exclusivo","Compartido"))) -> Compartido | H6: =--AND(B6=1,C6=0) -> 0 | I6: =--AND(B6=0,C6=1) -> 0
A7: HumanEval/154 | B7: 1 | C7: 1 | D7: 1 | E7: 0 | F7: =SUM(B7:E7) -> 3 | G7: =IF(F7=0,"Sin recuperación",IF(F7=4,"Robusto",IF(F7=1,"Exclusivo","Compartido"))) -> Compartido | H7: =--AND(B7=1,C7=0) -> 0 | I7: =--AND(B7=0,C7=1) -> 0
A8: HumanEval/50 | B8: 0 | C8: 0 | D8: 0 | E8: 0 | F8: =SUM(B8:E8) -> 0 | G8: =IF(F8=0,"Sin recuperación",IF(F8=4,"Robusto",IF(F8=1,"Exclusivo","Compartido"))) -> Sin recuperación | H8: =--AND(B8=1,C8=0) -> 0 | I8: =--AND(B8=0,C8=1) -> 0
A9: HumanEval/145 | B9: 0 | C9: 0 | D9: 0 | E9: 0 | F9: =SUM(B9:E9) -> 0 | G9: =IF(F9=0,"Sin recuperación",IF(F9=4,"Robusto",IF(F9=1,"Exclusivo","Compartido"))) -> Sin recuperación | H9: =--AND(B9=1,C9=0) -> 0 | I9: =--AND(B9=0,C9=1) -> 0
A10: HumanEval/163 | B10: 0 | C10: 0 | D10: 0 | E10: 0 | F10: =SUM(B10:E10) -> 0 | G10: =IF(F10=0,"Sin recuperación",IF(F10=4,"Robusto",IF(F10=1,"Exclusivo","Compartido"))) -> Sin recuperación | H10: =--AND(B10=1,C10=0) -> 0 | I10: =--AND(B10=0,C10=1) -> 0
A11: HumanEval/81 | B11: 1 | C11: 1 | D11: 1 | E11: 0 | F11: =SUM(B11:E11) -> 3 | G11: =IF(F11=0,"Sin recuperación",IF(F11=4,"Robusto",IF(F11=1,"Exclusivo","Compartido"))) -> Compartido | H11: =--AND(B11=1,C11=0) -> 0 | I11: =--AND(B11=0,C11=1) -> 0
A12: HumanEval/130 | B12: 0 | C12: 0 | D12: 0 | E12: 0 | F12: =SUM(B12:E12) -> 0 | G12: =IF(F12=0,"Sin recuperación",IF(F12=4,"Robusto",IF(F12=1,"Exclusivo","Compartido"))) -> Sin recuperación | H12: =--AND(B12=1,C12=0) -> 0 | I12: =--AND(B12=0,C12=1) -> 0
A13: HumanEval/121 | B13: 1 | C13: 0 | D13: 0 | E13: 0 | F13: =SUM(B13:E13) -> 1 | G13: =IF(F13=0,"Sin recuperación",IF(F13=4,"Robusto",IF(F13=1,"Exclusivo","Compartido"))) -> Exclusivo | H13: =--AND(B13=1,C13=0) -> 1 | I13: =--AND(B13=0,C13=1) -> 0
... A21: HumanEval/95 | B21: 0 | C21: 1 | D21: 1 | E21: 1 | F21: =SUM(B21:E21) -> 3 | G21: =IF(F21=0,"Sin recuperación",IF(F21=4,"Robusto",IF(F21=1,"Exclusivo","Compartido"))) -> Compartido | H21: =--AND(B21=1,C21=0) -> 0 | I21: =--AND(B21=0,C21=1) -> 1

Sheet Ramas
A1: task_id | B1: position | C1: top1_token | D1: top2_token | E1: entropy | F1: probability_margin | G1: semantic_score | H1: passed | I1: sel_semantic | J1: sel_entropy | K1: sel_margin | L1: sel_random | M1: latency_s | N1: error | O1: code
A2: HumanEval/10 | B2: 4 | C2: make | D2: is | E2: 0.61209083 | F2: 0.52107523 | G2: 0.45464853 | H2: 0 | I2: 0 | J2: 1 | K2: 1 | L2: 0 | M2: 12.547088 | N2: Traceback (most recent call last): File "/tmp/tmpue2nszzl/candidate.py", line 48, in <module> check(make_palindrome) File "/tmp/tmpue2nszzl/candidate.py", line 41, in check assert candidate('') == '' ^^^^^^^^^^^^^ File "/tmp/tmpue2nszzl/candidate.py", line 25, in make_palindrome if is_palindrome(string): ^^^^^^^^^^^^^ NameError: name 'is_palindrome' is not defined. Did you mean: 'make_palindrome'? | O2: ```python def is_palindrome(string: str) -> bool: """ Test if given string is a palindrome """ return string == string[::-1] def make_palindrome(string: str) -> str: """ Find the shortest palindrome that begins with a supplied string. Algorithm idea is simple: - Find the longest postfix of supplied string that is a palindrome. - Append to the end of the string reverse of a string prefix that comes before the palindromic suffix. >>> make_palindrome('') '' >>> make_palindrome('cat') 'catac' >>> make_palindrome('cata') 'catac' """ if is_palindrome(string): return string for i in range(len(string), -1, -1): if is_palindrome(string[i:]): return string + string[:i][::-1] return string ```
A3: HumanEval/10 | B3: 34 | C3: - | D3: """ | E3: 0.00010912886 | F3: 0.99998914 | G3: 0.85260771 | H3: 0 | I3: 1 | J3: 0 | K3: 0 | L3: 0 | M3: 3.1460506 | N3: Traceback (most recent call last): File "/tmp/tmpu93yl7ru/candidate.py", line 39, in <module> check(make_palindrome) File "/tmp/tmpu93yl7ru/candidate.py", line 32, in check assert candidate('') == '' ^^^^^^^^^^^^^ File "/tmp/tmpu93yl7ru/candidate.py", line 19, in make_palindrome if is_palindrome(string[:i]): ^^^^^^^^^^^^^ NameError: name 'is_palindrome' is not defined. Did you mean: 'make_palindrome'? | O3: ```python def make_palindrome(string: str) -> str: """ Find the shortest palindrome that begins with a supplied string. Algorithm idea is simple: """ n = len(string) for i in range(n, -1, -1): if is_palindrome(string[:i]): return string + string[i-1::-1] return string ```
A4: HumanEval/10 | B4: 63 | C4: before | D4: after | E4: 0.00044175194 | F4: 0.99993683 | G4: 0.15759637 | H4: 0 | I4: 0 | J4: 0 | K4: 0 | L4: 1 | M4: 6.2857217 | N4: Traceback (most recent call last): File "/tmp/tmpqi3agcgk/candidate.py", line 47, in <module> check(make_palindrome) File "/tmp/tmpqi3agcgk/candidate.py", line 40, in check assert candidate('') == '' ^^^^^^^^^^^^^ File "/tmp/tmpqi3agcgk/candidate.py", line 27, in make_palindrome if is_palindrome(string[:i]): ^^^^^^^^^^^^^ NameError: name 'is_palindrome' is not defined. Did you mean: 'make_palindrome'? | O4: ```python def make_palindrome(string: str) -> str: """ Find the shortest palindrome that begins with a supplied string. Algorithm idea is simple: - Find the longest postfix of supplied string that is a palindrome. - Append to the end of the string reverse of a string prefix that comes after the palindromic suffix. >>> make_palindrome('') '' >>> make_palindrome('cat') 'catac' >>> make_palindrome('cata') 'catac' """ n = len(string) for i in range(n, -1, -1): if is_palindrome(string[:i]): return string + string[i-1::-1] return string ```
A5: HumanEval/10 | B5: 111 | C5: if | D5: n | E5: 1.1748339 | F5: 0.05148676 | G5: 0.83786848 | H5: 0 | I5: 1 | J5: 1 | K5: 1 | L5: 0 | M5: 3.156506 | N5: Traceback (most recent call last): File "/tmp/tmpq2tbbpc9/candidate.py", line 47, in <module> check(make_palindrome) File "/tmp/tmpq2tbbpc9/candidate.py", line 40, in check assert candidate('') == '' ^^^^^^^^^^^^^ File "/tmp/tmpq2tbbpc9/candidate.py", line 27, in make_palindrome if is_palindrome(string[:i]): ^^^^^^^^^^^^^ NameError: name 'is_palindrome' is not defined. Did you mean: 'make_palindrome'? | O5: ```python def make_palindrome(string: str) -> str: """ Find the shortest palindrome that begins with a supplied string. Algorithm idea is simple: - Find the longest postfix of supplied string that is a palindrome. - Append to the end of the string reverse of a string prefix that comes before the palindromic suffix. >>> make_palindrome('') '' >>> make_palindrome('cat') 'catac' >>> make_palindrome('cata') 'catac' """ n = len(string) for i in range(n, -1, -1): if is_palindrome(string[:i]): return string + string[i-1::-1] return string ```
A6: HumanEval/10 | B6: 84 | C6: (' | D6: (" | E6: 1.0185161e-05 | F6: 0.9999991 | G6: 0.24263039 | H6: 0 | I6: 0 | J6: 0 | K6: 0 | L6: 1 | M6: 4.9721596 | N6: Traceback (most recent call last): File "/tmp/tmppyx_qmtw/candidate.py", line 47, in <module> check(make_palindrome) File "/tmp/tmppyx_qmtw/candidate.py", line 40, in check assert candidate('') == '' ^^^^^^^^^^^^^ File "/tmp/tmppyx_qmtw/candidate.py", line 27, in make_palindrome if is_palindrome(string[:i]): ^^^^^^^^^^^^^ NameError: name 'is_palindrome' is not defined. Did you mean: 'make_palindrome'? | O6: ```python def make_palindrome(string: str) -> str: """ Find the shortest palindrome that begins with a supplied string. Algorithm idea is simple: - Find the longest postfix of supplied string that is a palindrome. - Append to the end of the string reverse of a string prefix that comes before the palindromic suffix. >>> make_palindrome('') '' >>> make_palindrome("cat") 'catac' >>> make_palindrome("cata") 'catac' """ n = len(string) for i in range(n, -1, -1): if is_palindrome(string[:i]): return string + string[i-1::-1] return string ```
A7: HumanEval/10 | B7: 100 | C7: ata | D7: ATA | E7: 1.8228478e-05 | F7: 0.99999857 | G7: 0.37301587 | H7: 0 | I7: 0 | J7: 0 | K7: 0 | L7: 1 | M7: 3.8868964 | N7: Traceback (most recent call last): File "/tmp/tmpncukrvap/candidate.py", line 47, in <module> check(make_palindrome) File "/tmp/tmpncukrvap/candidate.py", line 40, in check assert candidate('') == '' ^^^^^^^^^^^^^ File "/tmp/tmpncukrvap/candidate.py", line 27, in make_palindrome if is_palindrome(string[:i]): ^^^^^^^^^^^^^ NameError: name 'is_palindrome' is not defined. Did you mean: 'make_palindrome'? | O7: ```python def make_palindrome(string: str) -> str: """ Find the shortest palindrome that begins with a supplied string. Algorithm idea is simple: - Find the longest postfix of supplied string that is a palindrome. - Append to the end of the string reverse of a string prefix that comes before the palindromic suffix. >>> make_palindrome('') '' >>> make_palindrome('cat') 'catac' >>> make_palindrome('cATA') 'cATAc' """ n = len(string) for i in range(n, -1, -1): if is_palindrome(string[:i]): return string + string[i-1::-1] return string ```
A8: HumanEval/10 | B8: 15 | C8: """ | D8: if | E8: 0.44127956 | F8: 0.875505 | G8: 0.81179138 | H8: 0 | I8: 1 | J8: 0 | K8: 0 | L8: 0 | M8: 3.378721 | N8: Traceback (most recent call last): File "/tmp/tmpn9oec4x4/candidate.py", line 37, in <module> check(make_palindrome) File "/tmp/tmpn9oec4x4/candidate.py", line 30, in check assert candidate('') == '' ^^^^^^^^^^^^^ File "/tmp/tmpn9oec4x4/candidate.py", line 14, in make_palindrome if is_palindrome(string): ^^^^^^^^^^^^^ NameError: name 'is_palindrome' is not defined. Did you mean: 'make_palindrome'? | O8: ```python def make_palindrome(string: str) -> str: if is_palindrome(string): return string for i in range(len(string), -1, -1): if is_palindrome(string[i:]): return string + string[:i][::-1] return string ```
A9: HumanEval/10 | B9: 26 | C9: . | D9: . | E9: 0.62395263 | F9: 0.63649124 | G9: 0.63492063 | H9: 0 | I9: 0 | J9: 1 | K9: 1 | L9: 0 | M9: 3.6128863 | N9: Traceback (most recent call last): File "/tmp/tmplj1boa8n/candidate.py", line 38, in <module> check(make_palindrome) File "/tmp/tmplj1boa8n/candidate.py", line 31, in check assert candidate('') == '' ^^^^^^^^^^^^^ File "/tmp/tmplj1boa8n/candidate.py", line 15, in make_palindrome if is_palindrome(string): ^^^^^^^^^^^^^ NameError: name 'is_palindrome' is not defined. Did you mean: 'make_palindrome'? | O9: ```python def make_palindrome(string: str) -> str: """ Find the shortest palindrome that begins with a supplied string. """ if is_palindrome(string): return string for i in range(len(string), -1, -1): if is_palindrome(string[:i]): return string + string[i-1::-1] return string ```
A10: HumanEval/10 | B10: 128 | C10: ), | D10: )): | E10: 0.73185289 | F10: 0.26996803 | G10: 0.75283447 | H10: 0 | I10: 0 | J10: 1 | K10: 1 | L10: 0 | M10: 2.0281003 | N10: Traceback (most recent call last): File "/tmp/tmpg58cw_vv/candidate.py", line 48, in <module> check(make_palindrome) File "/tmp/tmpg58cw_vv/candidate.py", line 41, in check assert candidate('') == '' ^^^^^^^^^^^^^ File "/tmp/tmpg58cw_vv/candidate.py", line 25, in make_palindrome if is_palindrome(string): ^^^^^^^^^^^^^ NameError: name 'is_palindrome' is not defined. Did you mean: 'make_palindrome'? | O10: ```python def make_palindrome(string: str) -> str: """ Find the shortest palindrome that begins with a supplied string. Algorithm idea is simple: - Find the longest postfix of supplied string that is a palindrome. - Append to the end of the string reverse of a string prefix that comes before the palindromic suffix. >>> make_palindrome('') '' >>> make_palindrome('cat') 'catac' >>> make_palindrome('cata') 'catac' """ if is_palindrome(string): return string for i in range(len(string)): if is_palindrome(string[i:]): return string + string[:i][::-1] return string ```
A11: HumanEval/10 | B11: 120 | E11: 1.0525669 | F11: 0.11145568 | G11: 0.12018141 | H11: 0 | I11: 0 | J11: 1 | K11: 1 | L11: 0 | M11: 2.6961181 | N11: Traceback (most recent call last): File "/tmp/tmp8__blhf2/candidate.py", line 48, in <module> check(make_palindrome) File "/tmp/tmp8__blhf2/candidate.py", line 41, in check assert candidate('') == '' ^^^^^^^^^^^^^ File "/tmp/tmp8__blhf2/candidate.py", line 25, in make_palindrome if is_palindrome(string): ^^^^^^^^^^^^^ NameError: name 'is_palindrome' is not defined. Did you mean: 'make_palindrome'? | O11: ```python def make_palindrome(string: str) -> str: """ Find the shortest palindrome that begins with a supplied string. Algorithm idea is simple: - Find the longest postfix of supplied string that is a palindrome. - Append to the end of the string reverse of a string prefix that comes before the palindromic suffix. >>> make_palindrome('') '' >>> make_palindrome('cat') 'catac' >>> make_palindrome('cata') 'catac' """ if is_palindrome(string): return string for i in range(len(string), -1, -1): if is_palindrome(string[i:]): return string + string[:i][::-1] ```
A12: HumanEval/10 | B12: 73 | C12: make | D12: assert | E12: 0.00015936809 | F12: 0.99998596 | G12: 0.69954649 | H12: 0 | I12: 0 | J12: 0 | K12: 0 | L12: 1 | M12: 5.9190355 | N12: Traceback (most recent call last): File "/tmp/tmp7r77g615/candidate.py", line 44, in <module> check(make_palindrome) File "/tmp/tmp7r77g615/candidate.py", line 37, in check assert candidate('') == '' ^^^^^^^^^^^^^ File "/tmp/tmp7r77g615/candidate.py", line 24, in make_palindrome if is_palindrome(string[:i]): ^^^^^^^^^^^^^ NameError: name 'is_palindrome' is not defined. Did you mean: 'make_palindrome'? | O12: ```python def make_palindrome(string: str) -> str: """ Find the shortest palindrome that begins with a supplied string. Algorithm idea is simple: - Find the longest postfix of supplied string that is a palindrome. - Append to the end of the string reverse of a string prefix that comes before the palindromic suffix. >>> assert make_palindrome('') == '' >>> assert make_palindrome('cat') == 'catac' >>> assert make_palindrome('cata') == 'catac' """ n = len(string) for i in range(n, -1, -1): if is_palindrome(string[:i]): return string + string[i-1::-1] return string ```
A13: HumanEval/10 | B13: 28 | C13: Algorithm | D13: """ | E13: 0.036888678 | F13: 0.9919888 | G13: 0.84353741 | H13: 0 | I13: 1 | J13: 0 | K13: 0 | L13: 0 | M13: 3.4922165 | N13: Traceback (most recent call last): File "/tmp/tmp0xc776e3/candidate.py", line 40, in <module> check(make_palindrome) File "/tmp/tmp0xc776e3/candidate.py", line 33, in check assert candidate('') == '' ^^^^^^^^^^^^^ File "/tmp/tmp0xc776e3/candidate.py", line 16, in make_palindrome if is_palindrome(string): ^^^^^^^^^^^^^ NameError: name 'is_palindrome' is not defined. Did you mean: 'make_palindrome'? | O13: ```python def make_palindrome(string: str) -> str: """ Find the shortest palindrome that begins with a supplied string. """ if is_palindrome(string): return string for i in range(len(string), -1, -1): if is_palindrome(string[:i]): prefix = string[i:] return string + prefix[::-1] ```
A14: HumanEval/10 | B14: 137 | C14: is | D14: string | E14: 0.0019857921 | F14: 0.99961708 | G14: 0.87188209 | H14: 0 | I14: 1 | J14: 0 | K14: 0 | L14: 0 | M14: 2.1254514 | N14: Traceback (most recent call last): File "/tmp/tmp_zu3t31_/candidate.py", line 48, in <module> check(make_palindrome) File "/tmp/tmp_zu3t31_/candidate.py", line 41, in check assert candidate('') == '' ^^^^^^^^^^^^^ File "/tmp/tmp_zu3t31_/candidate.py", line 25, in make_palindrome if is_palindrome(string): ^^^^^^^^^^^^^ NameError: name 'is_palindrome' is not defined. Did you mean: 'make_palindrome'? | O14: ```python def make_palindrome(string: str) -> str: """ Find the shortest palindrome that begins with a supplied string. Algorithm idea is simple: - Find the longest postfix of supplied string that is a palindrome. - Append to the end of the string reverse of a string prefix that comes before the palindromic suffix. >>> make_palindrome('') '' >>> make_palindrome('cat') 'catac' >>> make_palindrome('cata') 'catac' """ if is_palindrome(string): return string for i in range(len(string), -1, -1): if string[:i] == string[:i][::-1]: return string + string[i:][::-1] return string ```
A15: HumanEval/10 | B15: 37 | C15: longest | D15: long | E15: 3.5784782e-05 | F15: 0.9999966 | G15: 0.68594104 | H15: 0 | I15: 0 | J15: 0 | K15: 0 | L15: 1 | M15: 0.39287185 | N15: SyntaxError: unterminated triple-quoted string literal (detected at line 4) at line 2 | O15: ```python def make_palindrome(string: str) -> str: """ Find the shortest palindrome that begins with a supplied string. Algorithm idea is simple: - Find the longes ```
A16: HumanEval/121 | B16: 3 | C16: ): | D16: ): | E16: 0.036144357 | F16: 0.98873042 | G16: 0.725 | H16: 0 | I16: 1 | J16: 1 | K16: 1 | L16: 0 | M16: 2.1141102 | N16: Traceback (most recent call last): File "/tmp/tmpzae3fsbd/candidate.py", line 31, in <module> check(solution) File "/tmp/tmpzae3fsbd/candidate.py", line 19, in check assert candidate([5, 8, 7, 1]) == 12 ^^^^^^^^^^^^^^^^^^^^^^^^^^^^^^^^ AssertionError | O16: def solution(lst): return sum(x for i, x in enumerate(lst) if i % 2 == 1 and x % 2 == 1)
A17: HumanEval/121 | B17: 21 | C17: == | D17: != | E17: 0.0048796809 | F17: 0.9989759 | G17: 0.55 | H17: 0 | I17: 0 | J17: 0 | K17: 0 | L17: 1 | M17: 0.89068943 | N17: Traceback (most recent call last): File "/tmp/tmpxhuvxapt/candidate.py", line 31, in <module> check(solution) File "/tmp/tmpxhuvxapt/candidate.py", line 19, in check assert candidate([5, 8, 7, 1]) == 12 ^^^^^^^^^^^^^^^^^^^^^^^^^^^^^^^^ AssertionError | O17: def solution(lst): return sum(x for i, x in enumerate(lst) if i % 2 != 0 and x % 2 != 0)
A18: HumanEval/121 | B18: 9 | C18: i | D18: idx | E18: 0.012348763 | F18: 0.99723253 | G18: 0.24166667 | H18: 0 | I18: 0 | J18: 1 | K18: 1 | L18: 0 | M18: 1.6602809 | N18: Traceback (most recent call last): File "/tmp/tmpu3gw4yz1/candidate.py", line 31, in <module> check(solution) File "/tmp/tmpu3gw4yz1/candidate.py", line 19, in check assert candidate([5, 8, 7, 1]) == 12 ^^^^^^^^^^^^^^^^^^^^^^^^^^^^^^^^ AssertionError | O18: def solution(lst): return sum(x for idx, x in enumerate(lst) if idx % 2 == 1 and x % 2 == 1)
A19: HumanEval/121 | B19: 10 | C19: , | D19: ,x | E19: 0.001049726 | F19: 0.99983181 | G19: 0.64166667 | H19: 0 | I19: 0 | J19: 0 | K19: 0 | L19: 1 | M19: 1.5325147 | N19: Traceback (most recent call last): File "/tmp/tmpq2k1y2ll/candidate.py", line 31, in <module> check(solution) File "/tmp/tmpq2k1y2ll/candidate.py", line 19, in check assert candidate([5, 8, 7, 1]) == 12 ^^^^^^^^^^^^^^^^^^^^^^^^^^^^^^^^ AssertionError | O19: def solution(lst): return sum(x for i,x in enumerate(lst) if i % 2 == 1 and x % 2 == 1)
A20: HumanEval/121 | B20: 7 | C20: (x | D20: (lst | E20: 1.0632418 | F20: 0.068631291 | G20: 0.68333333 | H20: 0 | I20: 0 | J20: 1 | K20: 1 | L20: 0 | M20: 1.8581984 | N20: Traceback (most recent call last): File "/tmp/tmpi4hx_voi/candidate.py", line 31, in <module> check(solution) File "/tmp/tmpi4hx_voi/candidate.py", line 19, in check assert candidate([5, 8, 7, 1]) == 12 ^^^^^^^^^^^^^^^^^^^^^^^^^^^^^^^^ AssertionError | O20: def solution(lst): return sum(lst[i] for i in range(1, len(lst), 2) if lst[i] % 2 != 0)
A21: HumanEval/121 | B21: 19 | D21: 2 | E21: 5.0591289e-06 | F21: 0.99999948 | G21: 0.525 | H21: 0 | I21: 0 | J21: 0 | K21: 0 | L21: 1 | M21: 0.94877693 | N21: Traceback (most recent call last): File "/tmp/tmpcaira2i2/candidate.py", line 31, in <module> check(solution) File "/tmp/tmpcaira2i2/candidate.py", line 19, in check assert candidate([5, 8, 7, 1]) == 12 ^^^^^^^^^^^^^^^^^^^^^^^^^^^^^^^^ AssertionError | O21: def solution(lst): return sum(x for i, x in enumerate(lst) if i %2 == 1 and x % 2 == 1)
A22: HumanEval/121 | B22: 5 | C22: return | D22: """ | E22: 0.21295615 | F22: 0.91028087 | G22: 0.775 | H22: 0 | I22: 1 | J22: 1 | K22: 1 | L22: 0 | M22: 8.0423988 | N22: Traceback (most recent call last): File "/tmp/tmpb_si98xo/candidate.py", line 39, in <module> check(solution) File "/tmp/tmpb_si98xo/candidate.py", line 27, in check assert candidate([5, 8, 7, 1]) == 12 ^^^^^^^^^^^^^^^^^^^^^^^^^^^^^^^^ AssertionError | O22: def solution(lst): """Given a non-empty list of integers, return the sum of all of the odd elements that are in even positions. Examples solution([5, 8, 7, 1]) ==> 12 solution([3, 3, 3, 3, 3]) ==> 9 solution([30, 13, 24, 321]) ==>0 """ return sum(x for i, x in enumerate(lst) if i % 2 == 1 and x % 2 == 1)
A23: HumanEval/121 | B23: 16 | C23: if | D23: if | E23: 8.9630485e-05 | F23: 0.99999302 | G23: 0.23333333 | H23: 0 | I23: 0 | J23: 0 | K23: 0 | L23: 1 | M23: 1.212545 | N23: Traceback (most recent call last): File "/tmp/tmp91688d4f/candidate.py", line 31, in <module> check(solution) File "/tmp/tmp91688d4f/candidate.py", line 19, in check assert candidate([5, 8, 7, 1]) == 12 ^^^^^^^^^^^^^^^^^^^^^^^^^^^^^^^^ AssertionError | O23: def solution(lst): return sum(x for i, x in enumerate(lst) if i % 2 == 1 and x % 2 == 1)
A24: HumanEval/121 | B24: 15 | C24: ) | D24: , | E24: 0.042899508 | F24: 0.9866134 | G24: 0.81666667 | H24: 0 | I24: 1 | J24: 1 | K24: 1 | L24: 0 | M24: 1.5358419 | N24: Traceback (most recent call last): File "/tmp/tmp7b7xevqo/candidate.py", line 31, in <module> check(solution) File "/tmp/tmp7b7xevqo/candidate.py", line 19, in check assert candidate([5, 8, 7, 1]) == 12 ^^^^^^^^^^^^^^^^^^^^^^^^^^^^^^^^ AssertionError | O24: def solution(lst): return sum(x for i, x in enumerate(lst, start=1) if i % 2 == 0 and x % 2 != 0)
A25: HumanEval/121 | B25: 12 | C25: in | E25: 1.704301e-05 | F25: 0.99999865 | G25: 0.68333333 | H25: 0 | I25: 1 | J25: 0 | K25: 0 | L25: 0 | M25: 1.5301485 | N25: Traceback (most recent call last): File "/tmp/tmp3cvhs9go/candidate.py", line 31, in <module> check(solution) File "/tmp/tmp3cvhs9go/candidate.py", line 19, in check assert candidate([5, 8, 7, 1]) == 12 ^^^^^^^^^^^^^^^^^^^^^^^^^^^^^^^^ AssertionError | O25: def solution(lst): return sum(x for i, x in enumerate(lst) if i % 2 == 1 and x % 2 == 1)
A26: HumanEval/121 | B26: 13 | C26: enumerate | D26: enumerate | E26: 6.5375956e-05 | F26: 0.99999099 | G26: 0.15833333 | H26: 0 | I26: 0 | J26: 0 | K26: 0 | L26: 1 | M26: 1.4029302 | N26: SyntaxError: invalid syntax. Perhaps you forgot a comma? at line 2 | O26: def solution(lst): return sum(x for i, x inenumerate(lst) if i % 2 == 1 and x % 2 == 1)
A27: HumanEval/121 | B27: 20 | C27: 2 | E27: 1.7421501e-06 | F27: 0.99999981 | G27: 0.7 | H27: 1 | I27: 1 | J27: 0 | K27: 0 | L27: 0 | M27: 1.0180145 | O27: def solution(lst): return sum(x for i, x in enumerate(lst) if i % 2 == 0 and x % 2 != 0)
A28: HumanEval/127 | B28: 13 | C28: = | D28: 1 | E28: 1.0629148 | F28: 0.31427641 | G28: 0.70068027 | H28: 0 | I28: 0 | J28: 1 | K28: 1 | L28: 0 | M28: 8.4817299 | N28: Traceback (most recent call last): File "/tmp/tmpzr58v98n/candidate.py", line 44, in <module> check(intersection) File "/tmp/tmpzr58v98n/candidate.py", line 32, in check assert candidate((-1, 1), (0, 4)) == "NO" ^^^^^^^^^^^^^^^^^^^^^^^^^^^^^^^^^^ AssertionError | O28: ```python def intersection(interval1, interval2): start1, end1 = interval1 start2, end2 = interval2 max_start = max(start1, start2) min_end = min(end1, end2) if max_start > min_end: return "NO" intersection_length = min_end - max_start + 1 if intersection_length < 2: return "NO" for i in range(2, int(intersection_length**0.5) + 1): if intersection_length % i == 0: return "NO" return "YES" ```
A29: HumanEval/127 | B29: 95 | C29: i | E29: 1.2316206e-05 | F29: 0.9999988 | G29: 0.62414966 | H29: 0 | I29: 0 | J29: 0 | K29: 0 | L29: 1 | M29: 1.5049397 | N29: Traceback (most recent call last): File "/tmp/tmpybt1l3sj/candidate.py", line 42, in <module> check(intersection) File "/tmp/tmpybt1l3sj/candidate.py", line 30, in check assert candidate((-1, 1), (0, 4)) == "NO" ^^^^^^^^^^^^^^^^^^^^^^^^^^^^^^^^^^ AssertionError | O29: ```python def intersection(interval1, interval2): start = max(interval1[0], interval2[0]) end = min(interval1[1], interval2[1]) if start > end: return "NO" length = end - start + 1 if length < 2: return "NO" for i in range(2, int(length**0.5) + 1): if length % 2 == 0: return "NO" return "YES" ```
A30: HumanEval/127 | B30: 93 | C30: length | D30: (length | E30: 0.00019773521 | F30: 0.9999792 | G30: 0.27040816 | H30: 0 | I30: 0 | J30: 0 | K30: 0 | L30: 1 | M30: 1.4830828 | N30: Traceback (most recent call last): File "/tmp/tmpumtqm5yo/candidate.py", line 42, in <module> check(intersection) File "/tmp/tmpumtqm5yo/candidate.py", line 30, in check assert candidate((-1, 1), (0, 4)) == "NO" ^^^^^^^^^^^^^^^^^^^^^^^^^^^^^^^^^^ AssertionError | O30: ```python def intersection(interval1, interval2): start = max(interval1[0], interval2[0]) end = min(interval1[1], interval2[1]) if start > end: return "NO" length = end - start + 1 if length < 2: return "NO" for i in range(2, int(length**0.5) + 1): if(length % i == 0): return "NO" return "YES" ```
A31: HumanEval/127 | B31: 40 | C31: if | D31: length | E31: 0.43975449 | F31: 0.68729168 | G31: 0.82482993 | H31: 0 | I31: 0 | J31: 0 | K31: 1 | L31: 0 | M31: 4.1087328 | N31: Traceback (most recent call last): File "/tmp/tmpuet4yzcw/candidate.py", line 40, in <module> check(intersection) File "/tmp/tmpuet4yzcw/candidate.py", line 28, in check assert candidate((-1, 1), (0, 4)) == "NO" ^^^^^^^^^^^^^^^^^^^^^^^^^^^^^^^^^^ AssertionError | O31: ```python def intersection(interval1, interval2): start = max(interval1[0], interval2[0]) end = min(interval1[1], interval2[1]) length = end - start if length <= 0: return "NO" for i in range(2, int(length**0.5) + 1): if length % i == 0: return "NO" return "YES" ```
A32: HumanEval/127 | B32: 19 | C32: ], | D32: ] | E32: 3.8610586e-05 | F32: 0.99999522 | G32: 0.85204082 | H32: 0 | I32: 1 | J32: 0 | K32: 0 | L32: 0 | M32: 6.6565266 | N32: Traceback (most recent call last): File "/tmp/tmpstqddtij/candidate.py", line 40, in <module> check(intersection) File "/tmp/tmpstqddtij/candidate.py", line 27, in check assert candidate((1, 2), (2, 3)) == "NO" ^^^^^^^^^^^^^^^^^^^^^^^^^^^^^^^^^ AssertionError | O32: ```python def intersection(interval1, interval2): start = max(interval1[0] - 1, interval2[0] - 1) end = min(interval1[1] + 1, interval2[1] + 1) length = end - start if length <= 0: return "NO" for i in range(2, int(length**0.5) + 1): if length % i == 0: return "NO" return "YES" ```
A33: HumanEval/127 | B33: 4 | C33: intersection | D33: is | E33: 0.75529456 | F33: 0.046423346 | G33: 0.82142857 | H33: 0 | I33: 0 | J33: 1 | K33: 1 | L33: 0 | M33: 11.74757 | N33: Traceback (most recent call last): File "/tmp/tmplt1yvc86/candidate.py", line 37, in <module> check(intersection) File "/tmp/tmplt1yvc86/candidate.py", line 24, in check assert candidate((1, 2), (2, 3)) == "NO" ^^^^^^^^^^^^^^^^^^^^^^^^^ File "/tmp/tmplt1yvc86/candidate.py", line 19, in intersection return "YES" if is_prime(length) else "NO" ^^^^^^^^ NameError: name 'is_prime' is not defined | O33: ```python def is_prime(n): if n <= 1: return False if n <= 3: return True if n % 2 == 0 or n % 3 == 0: return False i = 5 while i * i <= n: if n % i == 0 or n % (i + 2) == 0: return False i += 6 return True def intersection(interval1, interval2): start = max(interval1[0], interval2[0]) end = min(interval1[1], interval2[1]) if start > end: return "NO" length = end - start + 1 return "YES" if is_prime(length) else "NO" ```
A34: HumanEval/127 | B34: 12 | C34: start | D34: def | E34: 0.59849674 | F34: 0.79444835 | G34: 0.86394558 | H34: 0 | I34: 1 | J34: 1 | K34: 0 | L34: 0 | M34: 8.1377504 | N34: Traceback (most recent call last): File "/tmp/tmpgwlqcafs/candidate.py", line 45, in <module> check(intersection) File "/tmp/tmpgwlqcafs/candidate.py", line 33, in check assert candidate((-1, 1), (0, 4)) == "NO" ^^^^^^^^^^^^^^^^^^^^^^^^^^^^^^^^^^ AssertionError | O34: ```python def intersection(interval1, interval2): def is_prime(n): if n <= 1: return False for i in range(2, int(n**0.5) + 1): if n % i == 0: return False return True start = max(interval1[0], interval2[0]) end = min(interval1[1], interval2[1]) if start > end: return "NO" length = end - start + 1 return "YES" if is_prime(length) else "NO" ```
A35: HumanEval/127 | B35: 33 | C35: ], | D35: ] | E35: 1.0297249e-05 | F35: 0.99999907 | G35: 0.85884354 | H35: 0 | I35: 1 | J35: 0 | K35: 0 | L35: 0 | M35: 5.12077 | N35: Traceback (most recent call last): File "/tmp/tmpc2w5e72o/candidate.py", line 40, in <module> check(intersection) File "/tmp/tmpc2w5e72o/candidate.py", line 27, in check assert candidate((1, 2), (2, 3)) == "NO" ^^^^^^^^^^^^^^^^^^^^^^^^^^^^^^^^^ AssertionError | O35: ```python def intersection(interval1, interval2): start = max(interval1[0], interval2[0]) end = min(interval1[1] + 1, interval2[1] + 1) length = end - start if length <= 0: return "NO" for i in range(2, int(length**0.5) + 1): if length % i == 0: return "NO" return "YES" ```
A36: HumanEval/127 | B36: 31 | C36: [ | D36: [- | E36: 2.2216278e-05 | F36: 0.99999724 | G36: 0.42176871 | H36: 0 | I36: 0 | J36: 0 | K36: 0 | L36: 1 | M36: 5.6542055 | N36: Traceback (most recent call last): File "/tmp/tmpb0s_5agm/candidate.py", line 42, in <module> check(intersection) File "/tmp/tmpb0s_5agm/candidate.py", line 30, in check assert candidate((-1, 1), (0, 4)) == "NO" ^^^^^^^^^^^^^^^^^^^^^^^^^^^^^^^^^^ AssertionError | O36: ```python def intersection(interval1, interval2): start = max(interval1[0], interval2[0]) end = min(interval1[-1], interval2[-1]) if start > end: return "NO" length = end - start + 1 if length < 2: return "NO" for i in range(2, int(length**0.5) + 1): if length % i == 0: return "NO" return "YES" ```
A37: HumanEval/127 | B37: 66 | C37: : | D37: or | E37: 0.0013835767 | F37: 0.99979001 | G37: 0.84183673 | H37: 0 | I37: 1 | J37: 0 | K37: 0 | L37: 0 | M37: 2.7656712 | N37: Traceback (most recent call last): File "/tmp/tmp9ska_djk/candidate.py", line 39, in <module> check(intersection) File "/tmp/tmp9ska_djk/candidate.py", line 27, in check assert candidate((-1, 1), (0, 4)) == "NO" ^^^^^^^^^^^^^^^^^^^^^^^^^^^^^^^^^^ AssertionError | O37: ```python def intersection(interval1, interval2): start = max(interval1[0], interval2[0]) end = min(interval1[1], interval2[1]) if start > end: return "NO" length = end - start + 1 if length < 2 or any(length % i == 0 for i in range(2, int(length**0.5) + 1)): return "NO" return "YES" ```
A38: HumanEval/127 | B38: 3 | C38: def | D38: from | E38: 0.2501063 | F38: 0.89897214 | G38: 0.85714286 | H38: 0 | I38: 1 | J38: 0 | K38: 0 | L38: 0 | M38: 12.166534 | N38: Traceback (most recent call last): File "/tmp/tmp8qgnih1k/candidate.py", line 39, in <module> check(intersection) File "/tmp/tmp8qgnih1k/candidate.py", line 26, in check assert candidate((1, 2), (2, 3)) == "NO" ^^^^^^^^^^^^^^^^^^^^^^^^^ File "/tmp/tmp8qgnih1k/candidate.py", line 21, in intersection return "YES" if is_prime(length) else "NO" ^^^^^^^^ NameError: name 'is_prime' is not defined | O38: ```python from math import sqrt def is_prime(n): if n <= 1: return False if n <= 3: return True if n % 2 == 0 or n % 3 == 0: return False i = 5 while i * i <= n: if n % i == 0 or n % (i + 2) == 0: return False i += 6 return True def intersection(interval1, interval2): start = max(interval1[0], interval2[0]) end = min(interval1[1], interval2[1]) if start > end: return "NO" length = end - start + 1 return "YES" if is_prime(length) else "NO" ```
A39: HumanEval/127 | B39: 63 | C39: < | D39: <= | E39: 0.54454237 | F39: 0.63570322 | G39: 0.53401361 | H39: 0 | I39: 0 | J39: 1 | K39: 1 | L39: 0 | M39: 3.5026132 | N39: Traceback (most recent call last): File "/tmp/tmp7lbnqnye/candidate.py", line 42, in <module> check(intersection) File "/tmp/tmp7lbnqnye/candidate.py", line 30, in check assert candidate((-1, 1), (0, 4)) == "NO" ^^^^^^^^^^^^^^^^^^^^^^^^^^^^^^^^^^ AssertionError | O39: ```python def intersection(interval1, interval2): start = max(interval1[0], interval2[0]) end = min(interval1[1], interval2[1]) if start > end: return "NO" length = end - start + 1 if length <= 1: return "NO" for i in range(2, int(length**0.5) + 1): if length % i == 0: return "NO" return "YES" ```
A40: HumanEval/127 | B40: 82 | C40: ** | D40: ** | E40: 0.4576456 | F40: 0.65787379 | G40: 0.61564626 | H40: 0 | I40: 0 | J40: 1 | K40: 1 | L40: 0 | M40: 2.2895274 | N40: Traceback (most recent call last): File "/tmp/tmp64g9smfh/candidate.py", line 42, in <module> check(intersection) File "/tmp/tmp64g9smfh/candidate.py", line 30, in check assert candidate((-1, 1), (0, 4)) == "NO" ^^^^^^^^^^^^^^^^^^^^^^^^^^^^^^^^^^ AssertionError | O40: ```python def intersection(interval1, interval2): start = max(interval1[0], interval2[0]) end = min(interval1[1], interval2[1]) if start > end: return "NO" length = end - start + 1 if length < 2: return "NO" for i in range(2, int(length ** 0.5) + 1): if length % i == 0: return "NO" return "YES" ```
...

Sheet Lookaheads
A1: task_id | B1: position | C1: top1_token | D1: top2_token | E1: entropy | F1: probability_margin | G1: semantic_score | H1: persistence | I1: semantic_divergence | J1: anchor_score | K1: full_branch_evaluated | L1: branch_passed | M1: estado
A2: HumanEval/10 | B2: 2 | E2: 0.014560952 | F2: 0.99666296 | H2: 0 | I2: 0 | J2: 0 | K2: 0 | M2: No evaluada completa
A3: HumanEval/10 | B3: 3 | C3: def | E3: 0.11586246 | F3: 0.96962449 | H3: 1 | I3: 0.49166667 | J3: 0 | K3: 0 | M3: No evaluada completa
A4: HumanEval/10 | B4: 4 | C4: make | D4: is | E4: 0.61209083 | F4: 0.52107523 | H4: 0.090909091 | I4: 0.1 | J4: 0.66666667 | K4: 1 | L4: 0 | M4: FAIL
A5: HumanEval/10 | B5: 5 | C5: _pal | D5: _short | E5: 0.00012350109 | F5: 0.99998518 | H5: 1 | I5: 0.40833333 | J5: 0.66666667 | K5: 0 | M5: No evaluada completa
A6: HumanEval/10 | B6: 6 | C6: indrome | D6: ind | E6: 1.6407572e-05 | F6: 0.99999863 | H6: 1 | I6: 0.43333333 | J6: 0.66666667 | K6: 0 | M6: No evaluada completa
A7: HumanEval/10 | B7: 7 | C7: (string | D7: (s | E7: 0.097741313 | F7: 0.96050802 | H7: 0.36363636 | I7: 0.225 | J7: 0.66666667 | K7: 0 | M7: No evaluada completa
A8: HumanEval/10 | B8: 8 | C8: : | D8: ): | E8: 0.0073655555 | F8: 0.99823438 | H8: 1 | I8: 0.42916667 | J8: 1 | K8: 0 | M8: No evaluada completa
A9: HumanEval/10 | B9: 9 | C9: str | E9: 3.6844984e-05 | F9: 0.99999647 | H9: 1 | I9: 0.47916667 | J9: 0.25925926 | K9: 0 | M9: No evaluada completa
A10: HumanEval/10 | B10: 10 | C10: ) | D10: ): | E10: 0.00013379272 | F10: 0.99998478 | H10: 1 | I10: 0.33333333 | J10: 0.83539095 | K10: 0 | M10: No evaluada completa
A11: HumanEval/10 | B11: 11 | C11: -> | D11: - | E11: 3.8421022e-05 | F11: 0.99999642 | H11: 1 | I11: 0.41666667 | J11: 1 | K11: 0 | M11: No evaluada completa
A12: HumanEval/10 | B12: 12 | C12: str | D12: str | E12: 3.4173827e-05 | F12: 0.99999726 | H12: 0 | I12: 0.016666667 | J12: 0 | K12: 0 | M12: No evaluada completa
A13: HumanEval/10 | B13: 13 | C13: : | D13: : | E13: 0.0012630292 | F13: 0.99979846 | H13: 1 | I13: 0.35 | J13: 0 | K13: 0 | M13: No evaluada completa
A14: HumanEval/10 | B14: 14 | E14: 0.00069862511 | F14: 0.99992859 | H14: 0 | I14: 0 | J14: 0 | K14: 0 | M14: No evaluada completa
A15: HumanEval/10 | B15: 15 | C15: """ | D15: if | E15: 0.44127956 | F15: 0.875505 | H15: 1 | I15: 0.44583333 | J15: 1 | K15: 1 | L15: 0 | M15: FAIL
A16: HumanEval/10 | B16: 16 | C16: Find | D16: Find | E16: 0.023189679 | F16: 0.99515881 | H16: 0.090909091 | I16: 0.016666667 | J16: 0 | K16: 0 | M16: No evaluada completa
A17: HumanEval/10 | B17: 17 | C17: the | D17: shortest | E17: 1.4650514e-05 | F17: 0.99999899 | H17: 1 | I17: 0.35 | J17: 0.66666667 | K17: 0 | M17: No evaluada completa
A18: HumanEval/10 | B18: 18 | C18: shortest | D18: short | E18: 0.00017582695 | F18: 0.99998333 | H18: 1 | I18: 0.35 | J18: 0.35 | K18: 0 | M18: No evaluada completa
A19: HumanEval/10 | B19: 19 | C19: palindrome | D19: palette | E19: 1.2845256e-05 | F19: 0.99999905 | H19: 0 | I19: 0.016666667 | J19: 0 | K19: 0 | M19: No evaluada completa
A20: HumanEval/10 | B20: 20 | C20: that | D20: starting | E20: 0.00032816222 | F20: 0.9999636 | H20: 1 | I20: 0.48333333 | J20: 0.8 | K20: 0 | M20: No evaluada completa
A21: HumanEval/10 | B21: 21 | C21: begins | D21: beings | E21: 0.00043616333 | F21: 0.99993268 | H21: 0 | I21: 0.016666667 | J21: 0 | K21: 0 | M21: No evaluada completa
A22: HumanEval/10 | B22: 22 | C22: with | D22: with | E22: 6.0473045e-05 | F22: 0.99999548 | H22: 0 | I22: 0.083333333 | J22: 0 | K22: 0 | M22: No evaluada completa
A23: HumanEval/10 | B23: 23 | C23: a | D23: the | E23: 0.0025024146 | F23: 0.9994772 | H23: 0.72727273 | I23: 0.22083333 | J23: 0.80099502 | K23: 0 | M23: No evaluada completa
A24: HumanEval/10 | B24: 24 | C24: supplied | D24: given | E24: 1.6934007e-05 | F24: 0.99999864 | H24: 0.81818182 | I24: 0.24166667 | J24: 0.94029851 | K24: 0 | M24: No evaluada completa
A25: HumanEval/10 | B25: 25 | C25: string | E25: 6.6826658e-05 | F25: 0.99999459 | H25: 1 | I25: 0.40833333 | J25: 0 | K25: 0 | M25: No evaluada completa
A26: HumanEval/10 | B26: 26 | C26: . | D26: . | E26: 0.62395263 | F26: 0.63649124 | H26: 0.90909091 | I26: 0.325 | J26: 1 | K26: 1 | L26: 0 | M26: FAIL
A27: HumanEval/10 | B27: 27 | E27: 0.0038050155 | F27: 0.99934694 | H27: 0.090909091 | I27: 0 | J27: 0 | K27: 0 | M27: No evaluada completa
A28: HumanEval/10 | B28: 28 | C28: Algorithm | D28: """ | E28: 0.036888678 | F28: 0.9919888 | H28: 1 | I28: 0.49583333 | J28: 1 | K28: 1 | L28: 0 | M28: FAIL
A29: HumanEval/10 | B29: 29 | C29: idea | D29: : | E29: 8.8860732e-05 | F29: 0.99999246 | H29: 1 | I29: 0.35416667 | J29: 0.45918367 | K29: 0 | M29: No evaluada completa
A30: HumanEval/10 | B30: 30 | C30: is | D30: : | E30: 0.00044771412 | F30: 0.99992546 | H30: 1 | I30: 0.35 | J30: 0 | K30: 0 | M30: No evaluada completa
A31: HumanEval/10 | B31: 31 | C31: simple | D31: as | E31: 0.0017705953 | F31: 0.99973761 | H31: 1 | I31: 0.325 | J31: 0.5 | K31: 0 | M31: No evaluada completa
A32: HumanEval/10 | B32: 32 | C32: : | D32: : | E32: 6.6286942e-05 | F32: 0.99999208 | H32: 1 | I32: 0.325 | J32: 0.32142857 | K32: 0 | M32: No evaluada completa
A33: HumanEval/10 | B33: 33 | E33: 0.00021466559 | F33: 0.99996615 | H33: 0 | I33: 0 | J33: 0 | K33: 0 | M33: No evaluada completa
A34: HumanEval/10 | B34: 34 | C34: - | D34: """ | E34: 0.00010912886 | F34: 0.99998914 | H34: 1 | I34: 0.50833333 | J34: 1 | K34: 1 | L34: 0 | M34: FAIL
A35: HumanEval/10 | B35: 35 | C35: Find | D35: Find | E35: 3.66436e-05 | F35: 0.99999719 | H35: 0 | I35: 0.016666667 | J35: 0 | K35: 0 | M35: No evaluada completa
A36: HumanEval/10 | B36: 36 | C36: the | D36: longest | E36: 5.5269302e-06 | F36: 0.99999961 | H36: 1 | I36: 0.325 | J36: 0.5 | K36: 0 | M36: No evaluada completa
A37: HumanEval/10 | B37: 37 | C37: longest | D37: long | E37: 3.5784782e-05 | F37: 0.9999966 | H37: 1 | I37: 0.47083333 | J37: 0.18367347 | K37: 1 | L37: 0 | M37: FAIL
A38: HumanEval/10 | B38: 38 | C38: postfix | D38: prefix | E38: 0.0024135287 | F38: 0.99967077 | H38: 0 | I38: 0.016666667 | J38: 0 | K38: 0 | M38: No evaluada completa
A39: HumanEval/10 | B39: 39 | C39: of | D39: that | E39: 0.00016248351 | F39: 0.99997582 | H39: 1 | I39: 0.41666667 | J39: 0 | K39: 0 | M39: No evaluada completa
A40: HumanEval/10 | B40: 40 | C40: supplied | D40: the | E40: 0.00025288545 | F40: 0.99995925 | H40: 1 | I40: 0.39166667 | J40: 0 | K40: 0 | M40: No evaluada completa
...
